<?xml version="1.0" encoding="utf-8" ?>
<!-- This URDF was automatically created by SolidWorks to URDF Exporter! Originally created by Stephen Brawner (brawner@gmail.com) 
     Commit Version: 1.6.0-4-g7f85cfe  Build Version: 1.6.7995.38578
     For more information, please see http://wiki.ros.org/sw_urdf_exporter -->
<robot name="airbot_play_v2_compatible_v1">
    <link name="base_link">
        <inertial>
            <origin xyz="-7.40129893089808E-05 4.73956588868989E-05 0.0319836979079202" rpy="0 0 0" />
            <mass value="0.106247734066052" />
            <inertia ixx="0.00005415" ixy="-0.00000023" ixz="-0.00000014" iyy="0.00005459" iyz="0.00000040" izz="0.00005079" />
        </inertial>
        <visual>
            <origin xyz="0 0 0" rpy="0 0 0" />
            <geometry>
                <mesh filename="package://airbot_play_v2_compatible_v1/meshes/base_link.STL" />
            </geometry>
            <material name="">
                <color rgba="0.752941176470588 0.752941176470588 0.752941176470588 1" />
            </material>
        </visual>
        <collision>
            <origin xyz="0 0 0" rpy="0 0 0" />
            <geometry>
                <mesh filename="package://airbot_play_v2_compatible_v1/meshes/base_link.STL" />
            </geometry>
        </collision>
    </link>
    <link name="link1">
        <inertial>
            <origin xyz="-0.000110401401159852 -5.9516073937115E-06 -0.0236545243595387" rpy="0 0 0" />
            <mass value="0.0289493292404144" />
            <inertia ixx="0.00003415" ixy="0.00000020" ixz="0.00000001" iyy="0.00001116" iyz="-0.00000027" izz="0.00003205" />
        </inertial>
        <visual>
            <origin xyz="0 0 0" rpy="0 0 0" />
            <geometry>
                <mesh filename="package://airbot_play_v2_compatible_v1/meshes/link1.STL" />
            </geometry>
            <material name="">
                <color rgba="0.752941176470588 0.752941176470588 0.752941176470588 1" />
            </material>
        </visual>
        <collision>
            <origin xyz="0 0 0" rpy="0 0 0" />
            <geometry>
                <mesh filename="package://airbot_play_v2_compatible_v1/meshes/link1.STL" />
            </geometry>
        </collision>
    </link>
    <joint name="joint1" type="revolute">
        <origin xyz="0 0 0.1005" rpy="0 0 0" />
        <parent link="base_link" />
        <child link="link1" />
        <axis xyz="0 0 1" />
        <limit lower="-2" upper="3.14" effort="100" velocity="110" />
    </joint>
    <link name="link2">
        <inertial>
            <origin xyz="0.131402178034658 0.000874874727492106 0.00146175650714369" rpy="0 0 0" />
            <mass value="0.279611367698844" />
            <inertia ixx="0.00016136" ixy="0.00000210" ixz="0.00000085" iyy="0.00386078" iyz="-0.00000053" izz="0.00384575" />
        </inertial>
        <visual>
            <origin xyz="0 0 0" rpy="0 0 0" />
            <geometry>
                <mesh filename="package://airbot_play_v2_compatible_v1/meshes/link2.STL" />
            </geometry>
            <material name="">
                <color rgba="0.752941176470588 0.752941176470588 0.752941176470588 1" />
            </material>
        </visual>
        <collision>
            <origin xyz="0 0 0" rpy="0 0 0" />
            <geometry>
                <mesh filename="package://airbot_play_v2_compatible_v1/meshes/link2.STL" />
            </geometry>
        </collision>
    </link>
    <joint name="joint2" type="revolute">
        <origin xyz="0 0 0" rpy="-1.5708 0 3.1326" />
        <parent link="link1" />
        <child link="link2" />
        <axis xyz="0 0 1" />
        <limit lower="-3.14" upper="0" effort="100" velocity="110" />
    </joint>
    <link name="link3">
        <inertial>
            <origin xyz="0.0436765172603279 -0.124217952682154 0.000863985483631766" rpy="0 0 0" />
            <mass value="0.122069188848913" />
            <inertia ixx="0.00115336" ixy="-0.00016476" ixz="-0.00000590" iyy="0.00013590" iyz="0.00001452" izz="0.00116357" />
        </inertial>
        <visual>
            <origin xyz="0 0 0" rpy="0 0 0" />
            <geometry>
                <mesh filename="package://airbot_play_v2_compatible_v1/meshes/link3.STL" />
            </geometry>
            <material name="">
                <color rgba="0.752941176470588 0.752941176470588 0.752941176470588 1" />
            </material>
        </visual>
        <collision>
            <origin xyz="0 0 0" rpy="0 0 0" />
            <geometry>
                <mesh filename="package://airbot_play_v2_compatible_v1/meshes/link3.STL" />
            </geometry>
        </collision>
    </link>
    <joint name="joint3" type="revolute">
        <origin xyz="0.264 0 0" rpy="0 0 -1.5708" />
        <parent link="link2" />
        <child link="link3" />
        <axis xyz="0 0 1" />
        <limit lower="0" upper="3.9" effort="100" velocity="110" />
    </joint>
    <link name="link4">
        <inertial>
            <origin xyz="0.00828390341909283 -0.000179999901881347 -0.0065769202471522" rpy="0 0 0" />
            <mass value="0.0554511336545199" />
            <inertia ixx="0.00003621" ixy="-0.00000009" ixz="-0.00000080" iyy="0.00003646" iyz="-0.00000004" izz="0.00002921" />
        </inertial>
        <visual>
            <origin xyz="0 0 0" rpy="0 0 0" />
            <geometry>
                <mesh filename="package://airbot_play_v2_compatible_v1/meshes/link4.STL" />
            </geometry>
            <material name="">
                <color rgba="0.752941176470588 0.752941176470588 0.752941176470588 1" />
            </material>
        </visual>
        <collision>
            <origin xyz="0 0 0" rpy="0 0 0" />
            <geometry>
                <mesh filename="package://airbot_play_v2_compatible_v1/meshes/link4.STL" />
            </geometry>
        </collision>
    </link>
    <joint name="joint4" type="revolute">
        <origin xyz="0.05675 -0.306 0" rpy="1.5708 0 0" />
        <parent link="link3" />
        <child link="link4" />
        <axis xyz="0 0 1" />
        <limit lower="-4" upper="4" effort="100" velocity="110" />
    </joint>
    <link name="link5">
        <inertial>
            <origin xyz="-0.0497295146243167 -0.000651142203663118 -0.00612845823429062" rpy="0 0 0" />
            <mass value="0.0671120133830051" />
            <inertia ixx="0.00003435" ixy="0.00000107" ixz="-0.00001436" iyy="0.00006703" iyz="-0.00000019" izz="0.00006201" />
        </inertial>
        <visual>
            <origin xyz="0 0 0" rpy="0 0 0" />
            <geometry>
                <mesh filename="package://airbot_play_v2_compatible_v1/meshes/link5.STL" />
            </geometry>
            <material name="">
                <color rgba="0.752941176470588 0.752941176470588 0.752941176470588 1" />
            </material>
        </visual>
        <collision>
            <origin xyz="0 0 0" rpy="0 0 0" />
            <geometry>
                <mesh filename="package://airbot_play_v2_compatible_v1/meshes/link5.STL" />
            </geometry>
        </collision>
    </link>
    <joint name="joint5" type="revolute">
        <origin xyz="0 0 0" rpy="-1.5708 1.5618 -1.5708" />
        <parent link="link4" />
        <child link="link5" />
        <axis xyz="0 0 1" />
        <limit lower="-1.4" upper="1.57" effort="100" velocity="110" />
    </joint>
    <link name="gripper_link">
        <inertial>
            <origin xyz="0 0 0" rpy="0 0 0" />
            <mass value="1E-15" />
            <inertia ixx="1E-11" ixy="1E-15" ixz="1E-15" iyy="1E-11" iyz="1E-15" izz="1E-11" />
        </inertial>
    </link>
    <joint name="joint6" type="revolute">
        <origin xyz="0 0 0" rpy="-1.5708 0 1.5708" />
        <parent link="link5" />
        <child link="gripper_link" />
        <axis xyz="0 0 1" />
        <limit lower="-10" upper="10" effort="100" velocity="1000" />
    </joint>
    <link name="custom_end_link">
        <inertial>
            <origin xyz="0 0 0" rpy="0 0 0" />
            <mass value="1E-15" />
            <inertia ixx="1E-11" ixy="1E-15" ixz="1E-15" iyy="1E-11" iyz="1E-15" izz="1E-11" />
        </inertial>
    </link>
    <joint name="joint_custom_end" type="fixed">
        <origin xyz="0 0 0.078" rpy="1.5708 -1.5708 0" />
        <parent link="gripper_link" />
        <child link="custom_end_link" />
    </joint>
    <transmission name="trans_joint1">
        <type>transmission_interface/SimpleTransmission</type>
        <joint name="joint1">
            <hardwareInterface>hardware_interface/PositionJointInterface</hardwareInterface>
        </joint>
        <actuator name="joint1_motor">
            <hardwareInterface>hardware_interface/PositionJointInterface</hardwareInterface>
            <mechanicalReduction>1</mechanicalReduction>
        </actuator>
    </transmission>
    <transmission name="trans_joint2">
        <type>transmission_interface/SimpleTransmission</type>
        <joint name="joint2">
            <hardwareInterface>hardware_interface/PositionJointInterface</hardwareInterface>
        </joint>
        <actuator name="joint2_motor">
            <hardwareInterface>hardware_interface/PositionJointInterface</hardwareInterface>
            <mechanicalReduction>1</mechanicalReduction>
        </actuator>
    </transmission>
    <transmission name="trans_joint3">
        <type>transmission_interface/SimpleTransmission</type>
        <joint name="joint3">
            <hardwareInterface>hardware_interface/PositionJointInterface</hardwareInterface>
        </joint>
        <actuator name="joint3_motor">
            <hardwareInterface>hardware_interface/PositionJointInterface</hardwareInterface>
            <mechanicalReduction>1</mechanicalReduction>
        </actuator>
    </transmission>
    <transmission name="trans_joint4">
        <type>transmission_interface/SimpleTransmission</type>
        <joint name="joint4">
            <hardwareInterface>hardware_interface/PositionJointInterface</hardwareInterface>
        </joint>
        <actuator name="joint4_motor">
            <hardwareInterface>hardware_interface/PositionJointInterface</hardwareInterface>
            <mechanicalReduction>1</mechanicalReduction>
        </actuator>
    </transmission>
    <transmission name="trans_joint5">
        <type>transmission_interface/SimpleTransmission</type>
        <joint name="joint5">
            <hardwareInterface>hardware_interface/PositionJointInterface</hardwareInterface>
        </joint>
        <actuator name="joint5_motor">
            <hardwareInterface>hardware_interface/PositionJointInterface</hardwareInterface>
            <mechanicalReduction>1</mechanicalReduction>
        </actuator>
    </transmission>
    <transmission name="trans_joint6">
        <type>transmission_interface/SimpleTransmission</type>
        <joint name="joint6">
            <hardwareInterface>hardware_interface/PositionJointInterface</hardwareInterface>
        </joint>
        <actuator name="joint6_motor">
            <hardwareInterface>hardware_interface/PositionJointInterface</hardwareInterface>
            <mechanicalReduction>1</mechanicalReduction>
        </actuator>
    </transmission>
    <gazebo>
        <plugin name="gazebo_ros_control">
            <robotNamespace>/</robotNamespace>
        </plugin>
    </gazebo>
</robot>

