<?xml version="1.0" encoding="utf-8" ?>
<!-- This URDF was automatically created by SolidWorks to URDF Exporter! Originally created by Stephen Brawner (brawner@gmail.com) 
     Commit Version: 1.6.0-4-g7f85cfe  Build Version: 1.6.7995.38578
     For more information, please see http://wiki.ros.org/sw_urdf_exporter -->
<robot name="ARX-5s-V5.0-urdf ceshi3">
    <mujoco>
        <compiler meshdir="../meshes/" balanceinertia="true" discardvisual="false" />
    </mujoco>
    <link name="base_link">
        <inertial>
            <origin xyz="-2.9949E-05 3.0537E-05 -0.033016" rpy="0 0 0" />
            <mass value="0.44071" />
            <inertia ixx="1.7392E-04" ixy="-3.4525E-07" ixz="-5.9337E-07" iyy="1.7547E-04" iyz="1.1271E-06" izz="1.5925E-04" />
        </inertial>
        <visual>
            <origin xyz="0 0 0" rpy="0 0 0" />
            <geometry>
                <mesh filename="package://airbot_play_compatible/meshes/base_link.STL" />
            </geometry>
            <material name="">
                <color rgba="0.75294 0.75294 0.75294 1" />
            </material>
        </visual>
        <collision>
            <origin xyz="0 0 0" rpy="0 0 0" />
            <geometry>
                <mesh filename="package://airbot_play_compatible/meshes/base_link.STL" />
            </geometry>
        </collision>
    </link>
    <link name="link1">
        <inertial>
            <origin xyz="-3.3048E-08 -0.00059451 0.016543" rpy="0 0 0" />
            <mass value="0.051342" />
            <inertia ixx="5.7689E-05" ixy="-7E-11" ixz="-3E-11" iyy="1.6943E-05" iyz="-3.3983E-07" izz="5.5562E-05" />
        </inertial>
        <visual>
            <origin xyz="0 0 0" rpy="0 0 0" />
            <geometry>
                <mesh filename="package://airbot_play_compatible/meshes/link1.STL" />
            </geometry>
            <material name="">
                <color rgba="1 1 1 1" />
            </material>
        </visual>
        <collision>
            <origin xyz="0 0 0" rpy="0 0 0" />
            <geometry>
                <mesh filename="package://airbot_play_compatible/meshes/link1.STL" />
            </geometry>
        </collision>
    </link>
    <joint name="joint1" type="revolute">
        <origin xyz="0 0 0" rpy="0 0 0" />
        <parent link="base_link" />
        <child link="link1" />
        <axis xyz="0 0 1" />
        <limit lower="-10" upper="10" effort="100" velocity="1000" />
    </joint>
    <link name="link2">
        <inertial>
            <origin xyz="0.13234 -0.00019055 -0.0019415" rpy="0 0 0" />
            <mass value="1.1379" />
            <inertia ixx="5.3430993E-04" ixy="-4.820824E-05" ixz="7.5502E-07" iyy="0" iyz="-2.6064E-07" izz="1.617805616E-02" />
        </inertial>
        <visual>
            <origin xyz="0 0 0" rpy="0 0 0" />
            <geometry>
                <mesh filename="package://airbot_play_compatible/meshes/link2.STL" />
            </geometry>
            <material name="">
                <color rgba="0.25098 0.25098 0.25098 1" />
            </material>
        </visual>
        <collision>
            <origin xyz="0 0 0" rpy="0 0 0" />
            <geometry>
                <mesh filename="package://airbot_play_compatible/meshes/link2.STL" />
            </geometry>
        </collision>
    </link>
    <joint name="joint2" type="revolute">
        <origin xyz="0 0 0.0402" rpy="-1.5708 0.0016463 3.1416" />
        <parent link="link1" />
        <child link="link2" />
        <axis xyz="0 0 1" />
        <limit lower="-10" upper="10" effort="100" velocity="1000" />
    </joint>
    <link name="link3">
        <inertial>
            <origin xyz="0.18498 0.0096239 8.209E-05" rpy="0 0 0" />
            <mass value="0.55615" />
            <inertia ixx="3.6463748E-04" ixy="-4.7568977E-04" ixz="-9.61418E-06" iyy="4.59290981E-03" iyz="-1.90857E-06" izz="4.61730434E-03" />
        </inertial>
        <visual>
            <origin xyz="0 0 0" rpy="0 0 0" />
            <geometry>
                <mesh filename="package://airbot_play_compatible/meshes/link3.STL" />
            </geometry>
            <material name="">
                <color rgba="0.75294 0.75294 0.75294 1" />
            </material>
        </visual>
        <collision>
            <origin xyz="0 0 0" rpy="0 0 0" />
            <geometry>
                <mesh filename="package://airbot_play_compatible/meshes/link3.STL" />
            </geometry>
        </collision>
    </link>
    <joint name="joint3" type="revolute">
        <origin xyz="0.264 0 0" rpy="0 0 -2.9169" />
        <parent link="link2" />
        <child link="link3" />
        <axis xyz="0 0 1" />
        <limit lower="-10" upper="10" effort="100" velocity="1000" />
    </joint>
    <link name="link4">
        <inertial>
            <origin xyz="0.05354 -0.0002508 -0.00056729" rpy="0 0 0" />
            <mass value="0.35037" />
            <inertia ixx="1.1078784E-04" ixy="5.68483E-06" ixz="-1.778429E-05" iyy="2.1478415E-04" iyz="-6.32521E-06" izz="1.6720967E-04" />
        </inertial>
        <visual>
            <origin xyz="0 0 0" rpy="0 0 0" />
            <geometry>
                <mesh filename="package://airbot_play_compatible/meshes/link4.STL" />
            </geometry>
            <material name="">
                <color rgba="0.89804 0.91765 0.92941 1" />
            </material>
        </visual>
        <collision>
            <origin xyz="0 0 0" rpy="0 0 0" />
            <geometry>
                <mesh filename="package://airbot_play_compatible/meshes/link4.STL" />
            </geometry>
        </collision>
    </link>
    <joint name="joint4" type="revolute">
        <origin xyz="0.25132 0 0" rpy="0 0 -0.22636" />
        <parent link="link3" />
        <child link="link4" />
        <axis xyz="0 0 1" />
        <limit lower="-10" upper="10" effort="100" velocity="1000" />
    </joint>
    <link name="link5">
        <inertial>
            <origin xyz="0.051613 -0.00072588 -0.00061659" rpy="0 0 0" />
            <mass value="0.33138" />
            <inertia ixx="3.1443063E-04" ixy="3.6082E-07" ixz="-7.6431E-07" iyy="2.9391628E-04" iyz="-1.8877E-07" izz="2.9233995E-04" />
        </inertial>
        <visual>
            <origin xyz="0 0 0" rpy="0 0 0" />
            <geometry>
                <mesh filename="package://airbot_play_compatible/meshes/link5.STL" />
            </geometry>
            <material name="">
                <color rgba="0.41176 0.41176 0.41176 1" />
            </material>
        </visual>
        <collision>
            <origin xyz="0 0 0" rpy="0 0 0" />
            <geometry>
                <mesh filename="package://airbot_play_compatible/meshes/link5.STL" />
            </geometry>
        </collision>
    </link>
    <joint name="joint5" type="revolute">
        <origin xyz="0.06 -0.0005 -0.002" rpy="-1.5708 -0.0025284 0" />
        <parent link="link4" />
        <child link="link5" />
        <axis xyz="0 0 1" />
        <limit lower="-10" upper="10" effort="100" velocity="1000" />
    </joint>
    <link name="link6">
        <inertial>
            <origin xyz="0 0 0" rpy="0 0 0" />
            <mass value="1E-09" />
            <inertia ixx="1E-09" ixy="1E-09" ixz="1E-09" iyy="1E-09" iyz="1E-09" izz="1E-09" />
        </inertial>
    </link>
    <joint name="joint6" type="revolute">
        <origin xyz="0.075 0 0" rpy="3.1416 -1.5708 0" />
        <parent link="link5" />
        <child link="link6" />
        <axis xyz="1 0 0" />
        <limit lower="-10" upper="10" effort="100" velocity="1000" />
    </joint>
    <transmission name="trans_joint1">
        <type>transmission_interface/SimpleTransmission</type>
        <joint name="joint1">
            <hardwareInterface>hardware_interface/PositionJointInterface</hardwareInterface>
        </joint>
        <actuator name="joint1_motor">
            <hardwareInterface>hardware_interface/PositionJointInterface</hardwareInterface>
            <mechanicalReduction>1</mechanicalReduction>
        </actuator>
    </transmission>
    <transmission name="trans_joint2">
        <type>transmission_interface/SimpleTransmission</type>
        <joint name="joint2">
            <hardwareInterface>hardware_interface/PositionJointInterface</hardwareInterface>
        </joint>
        <actuator name="joint2_motor">
            <hardwareInterface>hardware_interface/PositionJointInterface</hardwareInterface>
            <mechanicalReduction>1</mechanicalReduction>
        </actuator>
    </transmission>
    <transmission name="trans_joint3">
        <type>transmission_interface/SimpleTransmission</type>
        <joint name="joint3">
            <hardwareInterface>hardware_interface/PositionJointInterface</hardwareInterface>
        </joint>
        <actuator name="joint3_motor">
            <hardwareInterface>hardware_interface/PositionJointInterface</hardwareInterface>
            <mechanicalReduction>1</mechanicalReduction>
        </actuator>
    </transmission>
    <transmission name="trans_joint4">
        <type>transmission_interface/SimpleTransmission</type>
        <joint name="joint4">
            <hardwareInterface>hardware_interface/PositionJointInterface</hardwareInterface>
        </joint>
        <actuator name="joint4_motor">
            <hardwareInterface>hardware_interface/PositionJointInterface</hardwareInterface>
            <mechanicalReduction>1</mechanicalReduction>
        </actuator>
    </transmission>
    <transmission name="trans_joint5">
        <type>transmission_interface/SimpleTransmission</type>
        <joint name="joint5">
            <hardwareInterface>hardware_interface/PositionJointInterface</hardwareInterface>
        </joint>
        <actuator name="joint5_motor">
            <hardwareInterface>hardware_interface/PositionJointInterface</hardwareInterface>
            <mechanicalReduction>1</mechanicalReduction>
        </actuator>
    </transmission>
    <transmission name="trans_joint6">
        <type>transmission_interface/SimpleTransmission</type>
        <joint name="joint6">
            <hardwareInterface>hardware_interface/PositionJointInterface</hardwareInterface>
        </joint>
        <actuator name="joint6_motor">
            <hardwareInterface>hardware_interface/PositionJointInterface</hardwareInterface>
            <mechanicalReduction>1</mechanicalReduction>
        </actuator>
    </transmission>
    <gazebo>
        <plugin name="gazebo_ros_control">
            <robotNamespace>/</robotNamespace>
        </plugin>
    </gazebo>
</robot>

