<?xml version="1.0" encoding="utf-8"?>
<!-- This URDF was automatically created by SolidWorks to URDF Exporter! Originally created by Stephen Brawner (brawner@gmail.com) 
     Commit Version: 1.6.0-4-g7f85cfe  Build Version: 1.6.7995.38578
     For more information, please see http://wiki.ros.org/sw_urdf_exporter -->
<robot
  name="AirbotPlayTwoFinger">
  <mujoco>
    <compiler meshdir="../meshes/" balanceinertia="true" discardvisual="false" />
  </mujoco>
  <link
    name="base_link">
    <inertial>
      <origin
        xyz="-2.9949E-05 3.0537E-05 -0.033016"
        rpy="0 0 0" />
      <mass
        value="0.44071" />
      <inertia
        ixx="1.7392E-04"
        ixy="-3.4525E-07"
        ixz="-5.9337E-07"
        iyy="1.7547E-04"
        iyz="1.1271E-06"
        izz="1.5925E-04" />
    </inertial>
    <visual>
      <origin
        xyz="0 0 0"
        rpy="0 0 0" />
      <geometry>
        <mesh
          filename="package://airbot_play_twofinger/meshes/base_link.STL" />
      </geometry>
      <material
        name="">
        <color
          rgba="0.75294 0.75294 0.75294 1" />
      </material>
    </visual>
    <collision>
      <origin
        xyz="0 0 0"
        rpy="0 0 0" />
      <geometry>
        <mesh
          filename="package://airbot_play_twofinger/meshes/base_link.STL" />
      </geometry>
    </collision>
  </link>
  <link
    name="link1">
    <inertial>
      <origin
        xyz="-3.3048E-08 -0.00059451 0.016543"
        rpy="0 0 0" />
      <mass
        value="0.051342" />
      <inertia
        ixx="5.7689E-05"
        ixy="-7E-11"
        ixz="-3E-11"
        iyy="1.6943E-05"
        iyz="-3.3983E-07"
        izz="5.5562E-05" />
    </inertial>
    <visual>
      <origin
        xyz="0 0 0"
        rpy="0 0 0" />
      <geometry>
        <mesh
          filename="package://airbot_play_twofinger/meshes/link1.STL" />
      </geometry>
      <material
        name="">
        <color
          rgba="1 1 1 1" />
      </material>
    </visual>
    <collision>
      <origin
        xyz="0 0 0"
        rpy="0 0 0" />
      <geometry>
        <mesh
          filename="package://airbot_play_twofinger/meshes/link1.STL" />
      </geometry>
    </collision>
  </link>
  <joint
    name="joint1"
    type="revolute">
    <origin
      xyz="0 0 0"
      rpy="0 0 0" />
    <parent
      link="base_link" />
    <child
      link="link1" />
    <axis
      xyz="0 0 1" />
    <limit
      lower="-10"
      upper="10"
      effort="100"
      velocity="1000" />
  </joint>
  <link
    name="link2">
    <inertial>
      <origin
        xyz="0.13234 -0.00019055 -0.0019415"
        rpy="0 0 0" />
      <mass
        value="1.1379" />
      <inertia
        ixx="5.3430993E-04"
        ixy="-4.820824E-05"
        ixz="7.5502E-07"
        iyy="0"
        iyz="-2.6064E-07"
        izz="1.617805616E-02" />
    </inertial>
    <visual>
      <origin
        xyz="0 0 0"
        rpy="0 0 0" />
      <geometry>
        <mesh
          filename="package://airbot_play_twofinger/meshes/link2.STL" />
      </geometry>
      <material
        name="">
        <color
          rgba="0.25098 0.25098 0.25098 1" />
      </material>
    </visual>
    <collision>
      <origin
        xyz="0 0 0"
        rpy="0 0 0" />
      <geometry>
        <mesh
          filename="package://airbot_play_twofinger/meshes/link2.STL" />
      </geometry>
    </collision>
  </link>
  <joint
    name="joint2"
    type="revolute">
    <origin
      xyz="0 0 0.0402"
      rpy="-1.5708 0.0016463 3.1416" />
    <parent
      link="link1" />
    <child
      link="link2" />
    <axis
      xyz="0 0 1" />
    <limit
      lower="-10"
      upper="10"
      effort="100"
      velocity="1000" />
  </joint>
  <link
    name="link3">
    <inertial>
      <origin
        xyz="0.18498 0.0096239 8.209E-05"
        rpy="0 0 0" />
      <mass
        value="0.55615" />
      <inertia
        ixx="3.6463748E-04"
        ixy="-4.7568977E-04"
        ixz="-9.61418E-06"
        iyy="4.59290981E-03"
        iyz="-1.90857E-06"
        izz="4.61730434E-03" />
    </inertial>
    <visual>
      <origin
        xyz="0 0 0"
        rpy="0 0 0" />
      <geometry>
        <mesh
          filename="package://airbot_play_twofinger/meshes/link3.STL" />
      </geometry>
      <material
        name="">
        <color
          rgba="0.75294 0.75294 0.75294 1" />
      </material>
    </visual>
    <collision>
      <origin
        xyz="0 0 0"
        rpy="0 0 0" />
      <geometry>
        <mesh
          filename="package://airbot_play_twofinger/meshes/link3.STL" />
      </geometry>
    </collision>
  </link>
  <joint
    name="joint3"
    type="revolute">
    <origin
      xyz="0.264 0 0"
      rpy="0 0 -2.9169" />
    <parent
      link="link2" />
    <child
      link="link3" />
    <axis
      xyz="0 0 1" />
    <limit
      lower="-10"
      upper="10"
      effort="100"
      velocity="1000" />
  </joint>
  <link
    name="link4">
    <inertial>
      <origin
        xyz="0.05354 -0.0002508 -0.00056729"
        rpy="0 0 0" />
      <mass
        value="0.35037" />
      <inertia
        ixx="1.1078784E-04"
        ixy="5.68483E-06"
        ixz="-1.778429E-05"
        iyy="2.1478415E-04"
        iyz="-6.32521E-06"
        izz="1.6720967E-04" />
    </inertial>
    <visual>
      <origin
        xyz="0 0 0"
        rpy="0 0 0" />
      <geometry>
        <mesh
          filename="package://airbot_play_twofinger/meshes/link4.STL" />
      </geometry>
      <material
        name="">
        <color
          rgba="0.89804 0.91765 0.92941 1" />
      </material>
    </visual>
    <collision>
      <origin
        xyz="0 0 0"
        rpy="0 0 0" />
      <geometry>
        <mesh
          filename="package://airbot_play_twofinger/meshes/link4.STL" />
      </geometry>
    </collision>
  </link>
  <joint
    name="joint4"
    type="revolute">
    <origin
      xyz="0.25132 0 0"
      rpy="0 0 -0.22636" />
    <parent
      link="link3" />
    <child
      link="link4" />
    <axis
      xyz="0 0 1" />
    <limit
      lower="-10"
      upper="10"
      effort="100"
      velocity="1000" />
  </joint>
  <link
    name="link5">
    <inertial>
      <origin
        xyz="0.051613 -0.00072588 -0.00061659"
        rpy="0 0 0" />
      <mass
        value="0.33138" />
      <inertia
        ixx="3.1443063E-04"
        ixy="3.6082E-07"
        ixz="-7.6431E-07"
        iyy="2.9391628E-04"
        iyz="-1.8877E-07"
        izz="2.9233995E-04" />
    </inertial>
    <visual>
      <origin
        xyz="0 0 0"
        rpy="0 0 0" />
      <geometry>
        <mesh
          filename="package://airbot_play_twofinger/meshes/link5.STL" />
      </geometry>
      <material
        name="">
        <color
          rgba="0.41176 0.41176 0.41176 1" />
      </material>
    </visual>
    <collision>
      <origin
        xyz="0 0 0"
        rpy="0 0 0" />
      <geometry>
        <mesh
          filename="package://airbot_play_twofinger/meshes/link5.STL" />
      </geometry>
    </collision>
  </link>
  <joint
    name="joint5"
    type="revolute">
    <origin
      xyz="0.06 -0.0005 -0.002"
      rpy="-1.5708 -0.0025284 0" />
    <parent
      link="link4" />
    <child
      link="link5" />
    <axis
      xyz="0 0 1" />
    <limit
      lower="-10"
      upper="10"
      effort="100"
      velocity="1000" />
  </joint>
  <link
    name="connect_link">
    <inertial>
      <origin
        xyz="0 0 0"
        rpy="0 0 0" />
      <mass value="0.00001"/>
      <inertia
        ixx="6.34346460883134E-05"
        ixy="2.04299805834162E-05"
        ixz="-3.99923914087956E-08"
        iyy="5.24195258718733E-05"
        iyz="2.03068149625313E-08"
        izz="6.53446125054613E-05" />
      </inertial>
  </link>

  <joint
    name="joint6"
    type="revolute">
    <origin
      xyz="0.075 0 0"
      rpy="0 0 0" />
    <parent
      link="link5" />
    <child
      link="connect_link" />
    <axis
      xyz="1 0 0" />
    <limit
      lower="-10"
      upper="10"
      effort="100"
      velocity="1000" />
  </joint>

  <link
    name="base_link_g">
    <inertial>
      <origin
        xyz="0.00339303654278191 -2.1205433560656E-05 -0.0099185365078758"
        rpy="0 0 0" />
      <mass
        value="0.105853592307918" />
      <inertia
        ixx="3.93795927851199E-05"
        ixy="-8.7395226509728E-08"
        ixz="5.91928672040786E-07"
        iyy="0.000106376720416166"
        iyz="-1.82858764303774E-10"
        izz="0.000125852616063213" />
    </inertial>
    <visual>
      <origin
        xyz="0 0 0"
        rpy="0 0 0" />
      <geometry>
        <mesh
          filename="package://airbot_play_twofinger/meshes/base_link_g.STL" />
      </geometry>
      <material
        name="">
        <color
          rgba="0.894117647058823 0.913725490196078 0.929411764705882 1" />
      </material>
    </visual>
    <collision>
      <origin
        xyz="0 0 0"
        rpy="0 0 0" />
      <geometry>
        <mesh
          filename="package://airbot_play_twofinger/meshes/base_link_g.STL" />
      </geometry>
    </collision>
  </link>

  <joint
    name="connect_joint"
    type="fixed">
    <origin
      xyz="0.0457 0 0.01"
      rpy="0 0 0" />
    <parent
      link="connect_link" />
    <child
      link="base_link_g" />
    <axis
      xyz="1 0 0" />
  </joint>

  <link
    name="Link1">
    <inertial>
      <origin
        xyz="0.0164149658242926 9.75754915755189E-09 0.00898193900447147"
        rpy="0 0 0" />
      <mass
        value="0.00647716099397792" />
      <inertia
        ixx="2.95068972140683E-07"
        ixy="8.63208170411155E-13"
        ixz="-1.92008628754607E-09"
        iyy="1.69979619476872E-06"
        iyz="-1.99232397395103E-13"
        izz="1.45016449434989E-06" />
    </inertial>
    <visual>
      <origin
        xyz="0 0 0"
        rpy="0 0 0" />
      <geometry>
        <mesh
          filename="package://airbot_play_twofinger/meshes/Link1.STL" />
      </geometry>
      <material
        name="">
        <color
          rgba="0.894117647058823 0.913725490196078 0.929411764705882 1" />
      </material>
    </visual>
    <collision>
      <origin
        xyz="0 0 0"
        rpy="0 0 0" />
      <geometry>
        <mesh
          filename="package://airbot_play_twofinger/meshes/Link1.STL" />
      </geometry>
    </collision>
  </link>
  <joint
    name="Link1"
    type="revolute">
    <origin
      xyz="0.036 -0.04 -0.019"
      rpy="-3.0158E-16 -7.1586E-16 -0.30719" />
    <parent
      link="base_link_g" />
    <child
      link="Link1" />
    <axis
      xyz="0 0 1" />
    <limit
      lower="0"
      upper="1"
      effort="1"
      velocity="1" />
  </joint>
  <link
    name="Link11">
    <inertial>
      <origin
        xyz="0.011366555972498 0.0118642725662323 0.0060000073930068"
        rpy="0 0 0" />
      <mass
        value="0.0127543420299361" />
      <inertia
        ixx="5.68538478020233E-07"
        ixy="-2.68012262729007E-07"
        ixz="9.34125984931838E-13"
        iyy="1.45145776457487E-06"
        iyz="9.34355360561326E-13"
        izz="1.50564598220449E-06" />
    </inertial>
    <visual>
      <origin
        xyz="0 0 0"
        rpy="0 0 0" />
      <geometry>
        <mesh
          filename="package://airbot_play_twofinger/meshes/Link11.STL" />
      </geometry>
      <material
        name="">
        <color
          rgba="0.894117647058823 0.913725490196078 0.929411764705882 1" />
      </material>
    </visual>
    <collision>
      <origin
        xyz="0 0 0"
        rpy="0 0 0" />
      <geometry>
        <mesh
          filename="package://airbot_play_twofinger/meshes/Link11.STL" />
      </geometry>
    </collision>
  </link>
  <joint
    name="Link11"
    type="revolute">
    <origin
      xyz="0.042 0 0.003"
      rpy="5.0393E-16 5.6225E-16 0.30719" />
    <parent
      link="Link1" />
    <child
      link="Link11" />
    <axis
      xyz="0 0 1" />
    <limit
      lower="-1"
      upper="0"
      effort="1"
      velocity="1" />
  </joint>
  <link
    name="Link2">
    <inertial>
      <origin
        xyz="0.0164149658242926 9.75754915755189E-09 0.00898193900447147"
        rpy="0 0 0" />
      <mass
        value="0.00647716099397793" />
      <inertia
        ixx="2.95068972140683E-07"
        ixy="8.63208169650113E-13"
        ixz="-1.92008628755341E-09"
        iyy="1.69979619476872E-06"
        iyz="-1.99232397320157E-13"
        izz="1.45016449434989E-06" />
    </inertial>
    <visual>
      <origin
        xyz="0 0 0"
        rpy="0 0 0" />
      <geometry>
        <mesh
          filename="package://airbot_play_twofinger/meshes/Link2.STL" />
      </geometry>
      <material
        name="">
        <color
          rgba="0.894117647058823 0.913725490196078 0.929411764705882 1" />
      </material>
    </visual>
    <collision>
      <origin
        xyz="0 0 0"
        rpy="0 0 0" />
      <geometry>
        <mesh
          filename="package://airbot_play_twofinger/meshes/Link2.STL" />
      </geometry>
    </collision>
  </link>
  <joint
    name="Link2"
    type="revolute">
    <origin
      xyz="0.036 0.04 -0.019"
      rpy="-2.6397E-16 3.7199E-16 0.30719" />
    <parent
      link="base_link_g" />
    <child
      link="Link2" />
    <axis
      xyz="0 0 1" />
    <limit
      lower="-1"
      upper="0"
      effort="1"
      velocity="1" />
  </joint>
  <link
    name="Link22">
    <inertial>
      <origin
        xyz="-0.011366555972498 0.0118642725662323 -0.0060000073930068"
        rpy="0 0 0" />
      <mass
        value="0.0127543420299362" />
      <inertia
        ixx="5.68538478020238E-07"
        ixy="2.6801226272901E-07"
        ixz="9.34125986250171E-13"
        iyy="1.45145776457489E-06"
        iyz="-9.34355361631596E-13"
        izz="1.5056459822045E-06" />
    </inertial>
    <visual>
      <origin
        xyz="0 0 0"
        rpy="0 0 0" />
      <geometry>
        <mesh
          filename="package://airbot_play_twofinger/meshes/Link22.STL" />
      </geometry>
      <material
        name="">
        <color
          rgba="0.894117647058823 0.913725490196078 0.929411764705882 1" />
      </material>
    </visual>
    <collision>
      <origin
        xyz="0 0 0"
        rpy="0 0 0" />
      <geometry>
        <mesh
          filename="package://airbot_play_twofinger/meshes/Link22.STL" />
      </geometry>
    </collision>
  </link>
  <joint
    name="Link22"
    type="revolute">
    <origin
      xyz="0.042 0 0.015"
      rpy="-3.641E-16 2.4584E-16 2.8344" />
    <parent
      link="Link2" />
    <child
      link="Link22" />
    <axis
      xyz="0 0 1" />
    <limit
      lower="0"
      upper="1"
      effort="1"
      velocity="1" />
  </joint>
</robot>