<?xml version="1.0" encoding="utf-8" ?>
<!-- This URDF was automatically created by SolidWorks to URDF Exporter! Originally created by Stephen Brawner (brawner@gmail.com) 
     Commit Version: 1.6.0-4-g7f85cfe  Build Version: 1.6.7995.38578
     For more information, please see http://wiki.ros.org/sw_urdf_exporter -->
<robot name="airbot_play_inspire_eg2_4c_v2_gazebo">
    <link name="base_link">
        <inertial>
            <origin xyz="-2.9949E-05 3.0537E-05 0.027284" rpy="0 0 0" />
            <mass value="0.44071" />
            <inertia ixx="0.00017392" ixy="-3.5E-07" ixz="-5.9E-07" iyy="0.00017547" iyz="1.13E-06" izz="0.00015925" />
        </inertial>
        <visual>
            <origin xyz="0 0 0" rpy="0 0 0" />
            <geometry>
                <mesh filename="package://airbot_play_inspire_eg2_4c_v2_gazebo/meshes/base_link.STL" />
            </geometry>
            <material name="">
                <color rgba="0.75294 0.75294 0.75294 1" />
            </material>
        </visual>
        <collision>
            <origin xyz="0 0 0" rpy="0 0 0" />
            <geometry>
                <mesh filename="package://airbot_play_inspire_eg2_4c_v2_gazebo/meshes/base_link.STL" />
            </geometry>
        </collision>
    </link>
    <link name="link1">
        <inertial>
            <origin xyz="-0.00011034 -6.8411E-06 -0.023655" rpy="0 0 0" />
            <mass value="0.078163" />
            <inertia ixx="9.22E-05" ixy="-1E-08" ixz="5E-08" iyy="3.014E-05" iyz="-7.4E-07" izz="8.652E-05" />
        </inertial>
        <visual>
            <origin xyz="0 0 0" rpy="0 0 0" />
            <geometry>
                <mesh filename="package://airbot_play_inspire_eg2_4c_v2_gazebo/meshes/link1.STL" />
            </geometry>
            <material name="">
                <color rgba="0.75294 0.75294 0.75294 1" />
            </material>
        </visual>
        <collision>
            <origin xyz="0 0 0" rpy="0 0 0" />
            <geometry>
                <mesh filename="package://airbot_play_inspire_eg2_4c_v2_gazebo/meshes/link1.STL" />
            </geometry>
        </collision>
    </link>
    <joint name="joint1" type="revolute">
        <origin xyz="0 0 0.1005" rpy="0 0 0" />
        <parent link="base_link" />
        <child link="link1" />
        <axis xyz="0 0 1" />
        <limit lower="-10" upper="10" effort="100" velocity="110" />
    </joint>
    <link name="link2">
        <inertial>
            <origin xyz="0.13157 0.00062386 -0.0022903" rpy="0 0 0" />
            <mass value="1.0604" />
            <inertia ixx="0.00049116" ixy="5.47E-06" ixz="6.4E-07" iyy="0.01580055" iyz="1.04E-06" izz="0.01574902" />
        </inertial>
        <visual>
            <origin xyz="0 0 0" rpy="0 0 0" />
            <geometry>
                <mesh filename="package://airbot_play_inspire_eg2_4c_v2_gazebo/meshes/link2.STL" />
            </geometry>
            <material name="">
                <color rgba="0.75294 0.75294 0.75294 1" />
            </material>
        </visual>
        <collision>
            <origin xyz="0 0 0" rpy="0 0 0" />
            <geometry>
                <mesh filename="package://airbot_play_inspire_eg2_4c_v2_gazebo/meshes/link2.STL" />
            </geometry>
        </collision>
    </link>
    <joint name="joint2" type="revolute">
        <origin xyz="0 0 0" rpy="-1.5708 0 3.1416" />
        <parent link="link1" />
        <child link="link2" />
        <axis xyz="0 0 1" />
        <limit lower="-10" upper="10" effort="100" velocity="110" />
    </joint>
    <link name="link3">
        <inertial>
            <origin xyz="0.18065 0.0086528 0.0017767" rpy="0 0 0" />
            <mass value="0.55999" />
            <inertia ixx="0.00044245" ixy="-0.00043669" ixz="-9.35E-06" iyy="0.0052357" iyz="-9.31E-06" izz="0.0052474" />
        </inertial>
        <visual>
            <origin xyz="0 0 0" rpy="0 0 0" />
            <geometry>
                <mesh filename="package://airbot_play_inspire_eg2_4c_v2_gazebo/meshes/link3.STL" />
            </geometry>
            <material name="">
                <color rgba="0.75294 0.75294 0.75294 1" />
            </material>
        </visual>
        <collision>
            <origin xyz="0 0 0" rpy="0 0 0" />
            <geometry>
                <mesh filename="package://airbot_play_inspire_eg2_4c_v2_gazebo/meshes/link3.STL" />
            </geometry>
        </collision>
    </link>
    <joint name="joint3" type="revolute">
        <origin xyz="0.264 0 0" rpy="0 0 -2.9159" />
        <parent link="link2" />
        <child link="link3" />
        <axis xyz="0 0 1" />
        <limit lower="-10" upper="10" effort="100" velocity="110" />
    </joint>
    <link name="link4">
        <inertial>
            <origin xyz="0.054496 -0.0020302 0.0011432" rpy="0 0 0" />
            <mass value="0.34333" />
            <inertia ixx="0.00017672" ixy="2.2E-06" ixz="-1.227E-05" iyy="0.00026353" iyz="-5.14E-06" izz="0.00022296" />
        </inertial>
        <visual>
            <origin xyz="0 0 0" rpy="0 0 0" />
            <geometry>
                <mesh filename="package://airbot_play_inspire_eg2_4c_v2_gazebo/meshes/link4.STL" />
            </geometry>
            <material name="">
                <color rgba="0.75294 0.75294 0.75294 1" />
            </material>
        </visual>
        <collision>
            <origin xyz="0 0 0" rpy="0 0 0" />
            <geometry>
                <mesh filename="package://airbot_play_inspire_eg2_4c_v2_gazebo/meshes/link4.STL" />
            </geometry>
        </collision>
    </link>
    <joint name="joint4" type="revolute">
        <origin xyz="0.25137 0 -0.002" rpy="0 0 -0.22569" />
        <parent link="link3" />
        <child link="link4" />
        <axis xyz="0 0 1" />
        <limit lower="-10" upper="10" effort="100" velocity="110" />
    </joint>
    <link name="link5">
        <inertial>
            <origin xyz="-0.00042679 0.053307 0.00073106" rpy="0 0 0" />
            <mass value="0.33126" />
            <inertia ixx="0.00040201" ixy="1.6E-06" ixz="-5.07E-06" iyy="0.00042082" iyz="1.75E-06" izz="0.00036657" />
        </inertial>
        <visual>
            <origin xyz="0 0 0" rpy="0 0 0" />
            <geometry>
                <mesh filename="package://airbot_play_inspire_eg2_4c_v2_gazebo/meshes/link5.STL" />
            </geometry>
            <material name="">
                <color rgba="0.75294 0.75294 0.75294 1" />
            </material>
        </visual>
        <collision>
            <origin xyz="0 0 0" rpy="0 0 0" />
            <geometry>
                <mesh filename="package://airbot_play_inspire_eg2_4c_v2_gazebo/meshes/link5.STL" />
            </geometry>
        </collision>
    </link>
    <joint name="joint5" type="revolute">
        <origin xyz="0.06 0 0" rpy="-1.5708 -1.5708 0" />
        <parent link="link4" />
        <child link="link5" />
        <axis xyz="0 0 1" />
        <limit lower="-10" upper="10" effort="100" velocity="110" />
    </joint>
    <link name="gripper_link">
        <inertial>
            <origin xyz="-0.000179 -0.012920 0.118245" rpy="0 0 0" />
            <mass value="0.202483822224683" />
            <inertia ixx="8.72656224038094E-05" ixy="2.1157802312087E-09" ixz="4.46212258304102E-07" iyy="0.000110884338373626" iyz="3.53923491606382E-06" izz="9.50216775187288E-05" />
        </inertial>
        <visual>
            <origin xyz="0 0 0" rpy="0 0 0" />
            <geometry>
                <mesh filename="package://airbot_play_inspire_eg2_4c_v2_gazebo/meshes/gripper_link.STL" />
            </geometry>
            <material name="">
                <color rgba="0.792156862745098 0.819607843137255 0.933333333333333 1" />
            </material>
        </visual>
        <collision>
            <origin xyz="0 0 0" rpy="0 0 0" />
            <geometry>
                <mesh filename="package://airbot_play_inspire_eg2_4c_v2_gazebo/meshes/gripper_link.STL" />
            </geometry>
        </collision>
    </link>
    <joint name="joint6" type="revolute">
        <origin xyz="0 0 0" rpy="-1.5708 0 0" />
        <parent link="link5" />
        <child link="gripper_link" />
        <axis xyz="0 0 1" />
        <limit lower="-10" upper="10" effort="100" velocity="1000" />
    </joint>
    <link name="gripper_link10">
        <inertial>
            <origin xyz="0.0162376775855017 0.00170828143838967 1.60704782814491E-14" rpy="0 0 0" />
            <mass value="0.00248574193257273" />
            <inertia ixx="1.1187321281772E-07" ixy="-6.68088965340704E-19" ixz="-1.14085928959275E-18" iyy="6.84359115875508E-07" iyz="-3.99246934174549E-19" izz="5.89072994948579E-07" />
        </inertial>
        <visual>
            <origin xyz="0 0 0" rpy="0 0 0" />
            <geometry>
                <mesh filename="package://airbot_play_inspire_eg2_4c_v2_gazebo/meshes/gripper_link10.STL" />
            </geometry>
            <material name="">
                <color rgba="0.792156862745098 0.819607843137255 0.933333333333333 1" />
            </material>
        </visual>
        <collision>
            <origin xyz="0 0 0" rpy="0 0 0" />
            <geometry>
                <mesh filename="package://airbot_play_inspire_eg2_4c_v2_gazebo/meshes/gripper_link10.STL" />
            </geometry>
        </collision>
    </link>
    <joint name="joint_gripper10" type="revolute">
        <origin xyz="-0.038533 0.00036 0.18735" rpy="-1.5708 -1.304 3.1416" />
        <parent link="gripper_link" />
        <child link="gripper_link10" />
        <axis xyz="0 0 1" />
        <limit lower="-10" upper="10" effort="100" velocity="110" />
    </joint>
    <link name="gripper_link11">
        <inertial>
            <origin xyz="-0.0110043692378349 0.00972866237979003 -3.15436854414486E-09" rpy="0 0 0" />
            <mass value="0.00450681926243327" />
            <inertia ixx="1.99225999101227E-07" ixy="9.189631443366E-08" ixz="1.32669175648538E-13" iyy="5.14550853833888E-07" iyz="-4.49972931710022E-14" izz="5.32027763416069E-07" />
        </inertial>
        <visual>
            <origin xyz="0 0 0" rpy="0 0 0" />
            <geometry>
                <mesh filename="package://airbot_play_inspire_eg2_4c_v2_gazebo/meshes/gripper_link11.STL" />
            </geometry>
            <material name="">
                <color rgba="0.792156862745098 0.819607843137255 0.933333333333333 1" />
            </material>
        </visual>
        <collision>
            <origin xyz="0 0 0" rpy="0 0 0" />
            <geometry>
                <mesh filename="package://airbot_play_inspire_eg2_4c_v2_gazebo/meshes/gripper_link11.STL" />
            </geometry>
        </collision>
    </link>
    <joint name="joint_gripper11" type="revolute">
        <origin xyz="0.041998 -0.00037577 0" rpy="0 0 2.8658" />
        <parent link="gripper_link10" />
        <child link="gripper_link11" />
        <axis xyz="0 0 1" />
        <limit lower="-10" upper="10" effort="100" velocity="110" />
    </joint>
    <link name="gripper_link20">
        <inertial>
            <origin xyz="0.0160458916846533 0.00170815882510347 -1.61815005839117E-14" rpy="0 0 0" />
            <mass value="0.0024857419325728" />
            <inertia ixx="1.11873212817726E-07" ixy="6.5445041140093E-19" ixz="1.13838047913434E-18" iyy="6.84359115875493E-07" iyz="-3.98790262211301E-19" izz="5.8907299494856E-07" />
        </inertial>
        <visual>
            <origin xyz="0 0 0" rpy="0 0 0" />
            <geometry>
                <mesh filename="package://airbot_play_inspire_eg2_4c_v2_gazebo/meshes/gripper_link20.STL" />
            </geometry>
            <material name="">
                <color rgba="0.792156862745098 0.819607843137255 0.933333333333333 1" />
            </material>
        </visual>
        <collision>
            <origin xyz="0 0 0" rpy="0 0 0" />
            <geometry>
                <mesh filename="package://airbot_play_inspire_eg2_4c_v2_gazebo/meshes/gripper_link20.STL" />
            </geometry>
        </collision>
    </link>
    <joint name="joint_gripper20" type="revolute">
        <origin xyz="0.041464 0.00036 0.18664" rpy="1.5708 -1.304 0" />
        <parent link="gripper_link" />
        <child link="gripper_link20" />
        <axis xyz="0 0 1" />
        <limit lower="-10" upper="10" effort="100" velocity="110" />
    </joint>
    <link name="gripper_link21">
        <inertial>
            <origin xyz="-0.0117059608928904 -0.0140030860218414 3.11077152925776E-09" rpy="0 0 0" />
            <mass value="0.00450681912675432" />
            <inertia ixx="2.02615006762524E-07" ixy="-9.74786442765277E-08" ixz="-1.30502494006714E-13" iyy="5.11161832405036E-07" iyz="-4.71432886532517E-14" izz="5.32027750665231E-07" />
        </inertial>
        <visual>
            <origin xyz="0 0 0" rpy="0 0 0" />
            <geometry>
                <mesh filename="package://airbot_play_inspire_eg2_4c_v2_gazebo/meshes/gripper_link21.STL" />
            </geometry>
            <material name="">
                <color rgba="0.792156862745098 0.819607843137255 0.933333333333333 1" />
            </material>
        </visual>
        <collision>
            <origin xyz="0 0 0" rpy="0 0 0" />
            <geometry>
                <mesh filename="package://airbot_play_inspire_eg2_4c_v2_gazebo/meshes/gripper_link21.STL" />
            </geometry>
        </collision>
    </link>
    <joint name="joint_gripper21" type="revolute">
        <origin xyz="0.041998 -0.00037577 0" rpy="0 0 -2.8837" />
        <parent link="gripper_link20" />
        <child link="gripper_link21" />
        <axis xyz="0 0 1" />
        <limit lower="-10" upper="10" effort="100" velocity="110" />
    </joint>
    <link name="custom_end_link">
        <inertial>
            <origin xyz="0 0 0" rpy="0 0 0" />
            <mass value="1E-15" />
            <inertia ixx="1E-11" ixy="1E-15" ixz="1E-15" iyy="1E-11" iyz="1E-15" izz="1E-11" />
        </inertial>
    </link>
    <joint name="joint_custom_end" type="fixed">
        <origin xyz="0 0 0.255" rpy="1.5708 -1.5708 0" />
        <parent link="gripper_link" />
        <child link="custom_end_link" />
    </joint>
    <transmission name="trans_joint1">
        <type>transmission_interface/SimpleTransmission</type>
        <joint name="joint1">
            <hardwareInterface>hardware_interface/PositionJointInterface</hardwareInterface>
        </joint>
        <actuator name="joint1_motor">
            <hardwareInterface>hardware_interface/PositionJointInterface</hardwareInterface>
            <mechanicalReduction>1</mechanicalReduction>
        </actuator>
    </transmission>
    <transmission name="trans_joint2">
        <type>transmission_interface/SimpleTransmission</type>
        <joint name="joint2">
            <hardwareInterface>hardware_interface/PositionJointInterface</hardwareInterface>
        </joint>
        <actuator name="joint2_motor">
            <hardwareInterface>hardware_interface/PositionJointInterface</hardwareInterface>
            <mechanicalReduction>1</mechanicalReduction>
        </actuator>
    </transmission>
    <transmission name="trans_joint3">
        <type>transmission_interface/SimpleTransmission</type>
        <joint name="joint3">
            <hardwareInterface>hardware_interface/PositionJointInterface</hardwareInterface>
        </joint>
        <actuator name="joint3_motor">
            <hardwareInterface>hardware_interface/PositionJointInterface</hardwareInterface>
            <mechanicalReduction>1</mechanicalReduction>
        </actuator>
    </transmission>
    <transmission name="trans_joint4">
        <type>transmission_interface/SimpleTransmission</type>
        <joint name="joint4">
            <hardwareInterface>hardware_interface/PositionJointInterface</hardwareInterface>
        </joint>
        <actuator name="joint4_motor">
            <hardwareInterface>hardware_interface/PositionJointInterface</hardwareInterface>
            <mechanicalReduction>1</mechanicalReduction>
        </actuator>
    </transmission>
    <transmission name="trans_joint5">
        <type>transmission_interface/SimpleTransmission</type>
        <joint name="joint5">
            <hardwareInterface>hardware_interface/PositionJointInterface</hardwareInterface>
        </joint>
        <actuator name="joint5_motor">
            <hardwareInterface>hardware_interface/PositionJointInterface</hardwareInterface>
            <mechanicalReduction>1</mechanicalReduction>
        </actuator>
    </transmission>
    <transmission name="trans_joint6">
        <type>transmission_interface/SimpleTransmission</type>
        <joint name="joint6">
            <hardwareInterface>hardware_interface/PositionJointInterface</hardwareInterface>
        </joint>
        <actuator name="joint6_motor">
            <hardwareInterface>hardware_interface/PositionJointInterface</hardwareInterface>
            <mechanicalReduction>1</mechanicalReduction>
        </actuator>
    </transmission>
    <transmission name="trans_joint_gripper10">
        <type>transmission_interface/SimpleTransmission</type>
        <joint name="joint_gripper10">
            <hardwareInterface>hardware_interface/PositionJointInterface</hardwareInterface>
        </joint>
        <actuator name="joint_gripper10_motor">
            <hardwareInterface>hardware_interface/PositionJointInterface</hardwareInterface>
            <mechanicalReduction>1</mechanicalReduction>
        </actuator>
    </transmission>
    <transmission name="trans_joint_gripper11">
        <type>transmission_interface/SimpleTransmission</type>
        <joint name="joint_gripper11">
            <hardwareInterface>hardware_interface/PositionJointInterface</hardwareInterface>
        </joint>
        <actuator name="joint_gripper11_motor">
            <hardwareInterface>hardware_interface/PositionJointInterface</hardwareInterface>
            <mechanicalReduction>1</mechanicalReduction>
        </actuator>
    </transmission>
    <transmission name="trans_joint_gripper20">
        <type>transmission_interface/SimpleTransmission</type>
        <joint name="joint_gripper20">
            <hardwareInterface>hardware_interface/PositionJointInterface</hardwareInterface>
        </joint>
        <actuator name="joint_gripper20_motor">
            <hardwareInterface>hardware_interface/PositionJointInterface</hardwareInterface>
            <mechanicalReduction>1</mechanicalReduction>
        </actuator>
    </transmission>
    <transmission name="trans_joint_gripper21">
        <type>transmission_interface/SimpleTransmission</type>
        <joint name="joint_gripper21">
            <hardwareInterface>hardware_interface/PositionJointInterface</hardwareInterface>
        </joint>
        <actuator name="joint_gripper21_motor">
            <hardwareInterface>hardware_interface/PositionJointInterface</hardwareInterface>
            <mechanicalReduction>1</mechanicalReduction>
        </actuator>
    </transmission>
    <gazebo>
        <plugin name="gazebo_ros_control" filename="libgazebo_ros_control.so" >
            <robotNamespace>/</robotNamespace>
            <!-- <robotParam>/airbot_play/robot_description</robotParam> -->
        </plugin>
    </gazebo>
    <!-- Improve grasping physics -->
    <gazebo reference="gripper_link11">
      <ode>
        <kp>1000000.0</kp>
        <kd>1.0</kd>
        <mu1>100.0</mu1>
        <mu2>100.0</mu2>
        <minDepth>0.001</minDepth>
      </ode>
    </gazebo>
    <gazebo reference="gripper_link21">
      <ode>
        <kp>1000000.0</kp>
        <kd>1.0</kd>
        <mu1>100.0</mu1>
        <mu2>100.0</mu2>
        <minDepth>0.001</minDepth>
      </ode>
    </gazebo>
  <!-- Gazebo grasping plugin -->
  <gazebo>
    <gripper name="gazebo_gripper">
      <grasp_check>
        <attach_steps>2</attach_steps>    <!-- default: 20 -->
        <detach_steps>2</detach_steps>    <!-- default: 40 -->
        <min_contact_count>3</min_contact_count>
      </grasp_check>
      <gripper_link>gripper_link11</gripper_link>
      <gripper_link>gripper_link21</gripper_link>
      <palm_link>gripper_link</palm_link>
    </gripper>
  </gazebo>
  <!-- ROS base_link to UR 'Base' Coordinates transform -->
  <link name="base"/>
  <joint name="base_link-base_fixed_joint" type="fixed">
    <!-- NOTE: this rotation is only needed as long as base_link itself is
                 not corrected wrt the real robot (ie: rotated over 180
                 degrees)
      -->
    <origin rpy="0 0 0" xyz="0 0 0"/>
    <parent link="base_link"/>
    <child link="base"/>
  </joint>
  <!-- Frame coincident with all-zeros TCP on UR controller -->
  <link name="world"/>
  <joint name="world_joint" type="fixed">
    <parent link="world"/>
    <child link="base_link"/>
    <origin rpy="0.0 0.0 0.0" xyz="0.0 0.0 0.0"/>
  </joint>
</robot>