<?xml version="1.0" ?>
<!-- =================================================================================== -->
<!-- |    This document was autogenerated by xacro from /home/ghz/Work/airbot_play_models/src/assembled_models/airbot_play_v2_1_twins_v1/urdf/airbot_play_v2_1_twins_v1.xacro | -->
<!-- |    EDITING THIS FILE BY HAND IS NOT RECOMMENDED                                 | -->
<!-- =================================================================================== -->
<robot name="airbot_play_v2_1_twins_v1">
    <link name="left_base_link">
        <inertial>
            <origin rpy="0 0 0" xyz="-0.0106301474610337 -0.000199553410443472 0.0371964687357703" />
            <mass value="0.775915004746176" />
            <inertia ixx="0.00069985128784508" ixy="5.34514790296098E-06" ixz="1.76381070205361E-06" iyy="0.000855522012998859" iyz="3.90737393820019E-06" izz="0.00105821881122613" />
        </inertial>
        <visual>
            <origin rpy="0 0 0" xyz="0 0 0" />
            <geometry>
                <mesh filename="package://airbot_play_v2_1/meshes/base_link.STL" />
            </geometry>
            <material name="">
                <color rgba="0.898039215686275 0.917647058823529 0.929411764705882 1" />
            </material>
        </visual>
        <collision>
            <origin rpy="0 0 0" xyz="0 0 0" />
            <geometry>
                <mesh filename="package://airbot_play_v2_1/meshes/base_link.STL" />
            </geometry>
        </collision>
    </link>
    <link name="left_link1">
        <inertial>
            <origin rpy="0 0 0" xyz="7.26461828952265E-05 -0.00180358882481513 -0.0040245749975828" />
            <mass value="0.557107161361679" />
            <inertia ixx="0.000301325021461403" ixy="-2.99503777737959E-07" ixz="4.81746133283817E-07" iyy="0.000250217605970197" iyz="1.4954777872345E-05" izz="0.000325679218873344" />
        </inertial>
        <visual>
            <origin rpy="0 0 0" xyz="0 0 0" />
            <geometry>
                <mesh filename="package://airbot_play_v2_1/meshes/link1.STL" />
            </geometry>
            <material name="">
                <color rgba="0.898039215686275 0.917647058823529 0.929411764705882 1" />
            </material>
        </visual>
        <collision>
            <origin rpy="0 0 0" xyz="0 0 0" />
            <geometry>
                <mesh filename="package://airbot_play_v2_1/meshes/link1.STL" />
            </geometry>
        </collision>
    </link>
    <joint name="left_joint1" type="revolute">
        <origin rpy="0 0 0" xyz="0 0 0.1127" />
        <parent link="left_base_link" />
        <child link="left_link1" />
        <axis xyz="0 0 1" />
        <limit effort="0" lower="-3.14" upper="2.09" velocity="0" />
    </joint>
    <link name="left_link2">
        <inertial>
            <origin rpy="0 0 0" xyz="0.224925446535114 0.00478588811228768 0.00802387316222566" />
            <mass value="0.646248710360021" />
            <inertia ixx="0.000351883145335031" ixy="-7.83178613766434E-05" ixz="8.22450930417901E-05" iyy="0.00195260270078009" iyz="1.74744972718265E-05" izz="0.00195686017210086" />
        </inertial>
        <visual>
            <origin rpy="0 0 0" xyz="0 0 0" />
            <geometry>
                <mesh filename="package://airbot_play_v2_1/meshes/link2.STL" />
            </geometry>
            <material name="">
                <color rgba="1 1 1 1" />
            </material>
        </visual>
        <collision>
            <origin rpy="0 0 0" xyz="0 0 0" />
            <geometry>
                <mesh filename="package://airbot_play_v2_1/meshes/link2.STL" />
            </geometry>
        </collision>
    </link>
    <joint name="left_joint2" type="revolute">
        <origin rpy="-1.5708 -0.38678 3.1416" xyz="0 0 0" />
        <parent link="left_link1" />
        <child link="left_link2" />
        <axis xyz="0 0 1" />
        <limit effort="0" lower="-2.96" upper="0.17" velocity="0" />
    </joint>
    <link name="left_link3">
        <inertial>
            <origin rpy="0 0 0" xyz="0.200547330964236 -3.3627325386365E-05 0.00194896157935489" />
            <mass value="0.445563107671385" />
            <inertia ixx="0.000167369776419882" ixy="-4.81065732240346E-07" ixz="1.77949638222263E-06" iyy="0.000672322925427126" iyz="-9.83781152049909E-08" izz="0.000686599433660339" />
        </inertial>
        <visual>
            <origin rpy="0 0 0" xyz="0 0 0" />
            <geometry>
                <mesh filename="package://airbot_play_v2_1/meshes/link3.STL" />
            </geometry>
            <material name="">
                <color rgba="1 1 1 1" />
            </material>
        </visual>
        <collision>
            <origin rpy="0 0 0" xyz="0 0 0" />
            <geometry>
                <mesh filename="package://airbot_play_v2_1/meshes/link3.STL" />
            </geometry>
        </collision>
    </link>
    <joint name="left_joint3" type="revolute">
        <origin rpy="0 0 -2.7548" xyz="0.27009 1.3718E-05 0" />
        <parent link="left_link2" />
        <child link="left_link3" />
        <axis xyz="0 0 1" />
        <limit effort="0" lower="-0.087" upper="3.14" velocity="0" />
    </joint>
    <link name="left_link4">
        <inertial>
            <origin rpy="0 0 0" xyz="0.00150295453973709 5.83997713102176E-07 -0.00232966914421601" />
            <mass value="0.345884858675684" />
            <inertia ixx="0.000133803031406746" ixy="-7.29531827066913E-09" ixz="-2.46487819854503E-07" iyy="0.000121204730748505" iyz="9.89248496280094E-10" izz="0.000125010151603045" />
        </inertial>
        <visual>
            <origin rpy="0 0 0" xyz="0 0 0" />
            <geometry>
                <mesh filename="package://airbot_play_v2_1/meshes/link4.STL" />
            </geometry>
            <material name="">
                <color rgba="0.898039215686275 0.917647058823529 0.929411764705882 1" />
            </material>
        </visual>
        <collision>
            <origin rpy="0 0 0" xyz="0 0 0" />
            <geometry>
                <mesh filename="package://airbot_play_v2_1/meshes/link4.STL" />
            </geometry>
        </collision>
    </link>
    <joint name="left_joint4" type="revolute">
        <origin rpy="-1.5708 0 -1.5708" xyz="0.30854 0.0027492 0.00019049" />
        <parent link="left_link3" />
        <child link="left_link4" />
        <axis xyz="0 0 1" />
        <limit effort="0" lower="-2.96" upper="2.96" velocity="0" />
    </joint>
    <link name="left_link5">
        <inertial>
            <origin rpy="0 0 0" xyz="0.0506197654888128 6.95119841378662E-06 -0.000909972285324662" />
            <mass value="0.18663635710924" />
            <inertia ixx="0.000101780959048711" ixy="-1.53592986463846E-08" ixz="5.24140905704508E-08" iyy="8.2787133363287E-05" iyz="-1.71995563550468E-08" izz="8.59347793251101E-05" />
        </inertial>
        <visual>
            <origin rpy="0 0 0" xyz="0 0 0" />
            <geometry>
                <mesh filename="package://airbot_play_v2_1/meshes/link5.STL" />
            </geometry>
            <material name="">
                <color rgba="0.898039215686275 0.917647058823529 0.929411764705882 1" />
            </material>
        </visual>
        <collision>
            <origin rpy="0 0 0" xyz="0 0 0" />
            <geometry>
                <mesh filename="package://airbot_play_v2_1/meshes/link5.STL" />
            </geometry>
        </collision>
    </link>
    <joint name="left_joint5" type="revolute">
        <origin rpy="0 -1.5708 0" xyz="0 0 0" />
        <parent link="left_link4" />
        <child link="left_link5" />
        <axis xyz="0 0 1" />
        <limit effort="0" lower="-1.74" upper="1.74" velocity="0" />
    </joint>
    <link name="left_link6">
        <inertial>
            <origin rpy="0 0 0" xyz="1.11022302462516E-16 -1.30602993697604E-15 -0.023" />
            <mass value="0.17462115508378" />
            <inertia ixx="5.00435126944266E-05" ixy="8.85914841130682E-35" ixz="-1.77933387786267E-21" iyy="5.00435126944266E-05" iyz="-7.56774997864734E-35" izz="3.85039646959735E-05" />
        </inertial>
        <visual>
            <origin rpy="0 0 0" xyz="0 0 0" />
            <geometry>
                <mesh filename="package://airbot_play_v2_1/meshes/link6.STL" />
            </geometry>
            <material name="">
                <color rgba="0.698039215686274 0.698039215686274 0.698039215686274 1" />
            </material>
        </visual>
        <collision>
            <origin rpy="0 0 0" xyz="0 0 0" />
            <geometry>
                <mesh filename="package://airbot_play_v2_1/meshes/link6.STL" />
            </geometry>
        </collision>
    </link>
    <joint name="left_joint6" type="revolute">
        <origin rpy="0 1.5708 0" xyz="0.0865 0 -0.0027486" />
        <parent link="left_link5" />
        <child link="left_link6" />
        <axis xyz="0 0 1" />
        <limit effort="0" lower="-3.14" upper="3.14" velocity="0" />
    </joint>
    <link name="right_base_link">
        <inertial>
            <origin rpy="0 0 0" xyz="-0.0106301474610337 -0.000199553410443472 0.0371964687357703" />
            <mass value="0.775915004746176" />
            <inertia ixx="0.00069985128784508" ixy="5.34514790296098E-06" ixz="1.76381070205361E-06" iyy="0.000855522012998859" iyz="3.90737393820019E-06" izz="0.00105821881122613" />
        </inertial>
        <visual>
            <origin rpy="0 0 0" xyz="0 0 0" />
            <geometry>
                <mesh filename="package://airbot_play_v2_1/meshes/base_link.STL" />
            </geometry>
            <material name="">
                <color rgba="0.898039215686275 0.917647058823529 0.929411764705882 1" />
            </material>
        </visual>
        <collision>
            <origin rpy="0 0 0" xyz="0 0 0" />
            <geometry>
                <mesh filename="package://airbot_play_v2_1/meshes/base_link.STL" />
            </geometry>
        </collision>
    </link>
    <link name="right_link1">
        <inertial>
            <origin rpy="0 0 0" xyz="7.26461828952265E-05 -0.00180358882481513 -0.0040245749975828" />
            <mass value="0.557107161361679" />
            <inertia ixx="0.000301325021461403" ixy="-2.99503777737959E-07" ixz="4.81746133283817E-07" iyy="0.000250217605970197" iyz="1.4954777872345E-05" izz="0.000325679218873344" />
        </inertial>
        <visual>
            <origin rpy="0 0 0" xyz="0 0 0" />
            <geometry>
                <mesh filename="package://airbot_play_v2_1/meshes/link1.STL" />
            </geometry>
            <material name="">
                <color rgba="0.898039215686275 0.917647058823529 0.929411764705882 1" />
            </material>
        </visual>
        <collision>
            <origin rpy="0 0 0" xyz="0 0 0" />
            <geometry>
                <mesh filename="package://airbot_play_v2_1/meshes/link1.STL" />
            </geometry>
        </collision>
    </link>
    <joint name="right_joint1" type="revolute">
        <origin rpy="0 0 0" xyz="0 0 0.1127" />
        <parent link="right_base_link" />
        <child link="right_link1" />
        <axis xyz="0 0 1" />
        <limit effort="0" lower="-3.14" upper="2.09" velocity="0" />
    </joint>
    <link name="right_link2">
        <inertial>
            <origin rpy="0 0 0" xyz="0.224925446535114 0.00478588811228768 0.00802387316222566" />
            <mass value="0.646248710360021" />
            <inertia ixx="0.000351883145335031" ixy="-7.83178613766434E-05" ixz="8.22450930417901E-05" iyy="0.00195260270078009" iyz="1.74744972718265E-05" izz="0.00195686017210086" />
        </inertial>
        <visual>
            <origin rpy="0 0 0" xyz="0 0 0" />
            <geometry>
                <mesh filename="package://airbot_play_v2_1/meshes/link2.STL" />
            </geometry>
            <material name="">
                <color rgba="1 1 1 1" />
            </material>
        </visual>
        <collision>
            <origin rpy="0 0 0" xyz="0 0 0" />
            <geometry>
                <mesh filename="package://airbot_play_v2_1/meshes/link2.STL" />
            </geometry>
        </collision>
    </link>
    <joint name="right_joint2" type="revolute">
        <origin rpy="-1.5708 -0.38678 3.1416" xyz="0 0 0" />
        <parent link="right_link1" />
        <child link="right_link2" />
        <axis xyz="0 0 1" />
        <limit effort="0" lower="-2.96" upper="0.17" velocity="0" />
    </joint>
    <link name="right_link3">
        <inertial>
            <origin rpy="0 0 0" xyz="0.200547330964236 -3.3627325386365E-05 0.00194896157935489" />
            <mass value="0.445563107671385" />
            <inertia ixx="0.000167369776419882" ixy="-4.81065732240346E-07" ixz="1.77949638222263E-06" iyy="0.000672322925427126" iyz="-9.83781152049909E-08" izz="0.000686599433660339" />
        </inertial>
        <visual>
            <origin rpy="0 0 0" xyz="0 0 0" />
            <geometry>
                <mesh filename="package://airbot_play_v2_1/meshes/link3.STL" />
            </geometry>
            <material name="">
                <color rgba="1 1 1 1" />
            </material>
        </visual>
        <collision>
            <origin rpy="0 0 0" xyz="0 0 0" />
            <geometry>
                <mesh filename="package://airbot_play_v2_1/meshes/link3.STL" />
            </geometry>
        </collision>
    </link>
    <joint name="right_joint3" type="revolute">
        <origin rpy="0 0 -2.7548" xyz="0.27009 1.3718E-05 0" />
        <parent link="right_link2" />
        <child link="right_link3" />
        <axis xyz="0 0 1" />
        <limit effort="0" lower="-0.087" upper="3.14" velocity="0" />
    </joint>
    <link name="right_link4">
        <inertial>
            <origin rpy="0 0 0" xyz="0.00150295453973709 5.83997713102176E-07 -0.00232966914421601" />
            <mass value="0.345884858675684" />
            <inertia ixx="0.000133803031406746" ixy="-7.29531827066913E-09" ixz="-2.46487819854503E-07" iyy="0.000121204730748505" iyz="9.89248496280094E-10" izz="0.000125010151603045" />
        </inertial>
        <visual>
            <origin rpy="0 0 0" xyz="0 0 0" />
            <geometry>
                <mesh filename="package://airbot_play_v2_1/meshes/link4.STL" />
            </geometry>
            <material name="">
                <color rgba="0.898039215686275 0.917647058823529 0.929411764705882 1" />
            </material>
        </visual>
        <collision>
            <origin rpy="0 0 0" xyz="0 0 0" />
            <geometry>
                <mesh filename="package://airbot_play_v2_1/meshes/link4.STL" />
            </geometry>
        </collision>
    </link>
    <joint name="right_joint4" type="revolute">
        <origin rpy="-1.5708 0 -1.5708" xyz="0.30854 0.0027492 0.00019049" />
        <parent link="right_link3" />
        <child link="right_link4" />
        <axis xyz="0 0 1" />
        <limit effort="0" lower="-2.96" upper="2.96" velocity="0" />
    </joint>
    <link name="right_link5">
        <inertial>
            <origin rpy="0 0 0" xyz="0.0506197654888128 6.95119841378662E-06 -0.000909972285324662" />
            <mass value="0.18663635710924" />
            <inertia ixx="0.000101780959048711" ixy="-1.53592986463846E-08" ixz="5.24140905704508E-08" iyy="8.2787133363287E-05" iyz="-1.71995563550468E-08" izz="8.59347793251101E-05" />
        </inertial>
        <visual>
            <origin rpy="0 0 0" xyz="0 0 0" />
            <geometry>
                <mesh filename="package://airbot_play_v2_1/meshes/link5.STL" />
            </geometry>
            <material name="">
                <color rgba="0.898039215686275 0.917647058823529 0.929411764705882 1" />
            </material>
        </visual>
        <collision>
            <origin rpy="0 0 0" xyz="0 0 0" />
            <geometry>
                <mesh filename="package://airbot_play_v2_1/meshes/link5.STL" />
            </geometry>
        </collision>
    </link>
    <joint name="right_joint5" type="revolute">
        <origin rpy="0 -1.5708 0" xyz="0 0 0" />
        <parent link="right_link4" />
        <child link="right_link5" />
        <axis xyz="0 0 1" />
        <limit effort="0" lower="-1.74" upper="1.74" velocity="0" />
    </joint>
    <link name="right_link6">
        <inertial>
            <origin rpy="0 0 0" xyz="1.11022302462516E-16 -1.30602993697604E-15 -0.023" />
            <mass value="0.17462115508378" />
            <inertia ixx="5.00435126944266E-05" ixy="8.85914841130682E-35" ixz="-1.77933387786267E-21" iyy="5.00435126944266E-05" iyz="-7.56774997864734E-35" izz="3.85039646959735E-05" />
        </inertial>
        <visual>
            <origin rpy="0 0 0" xyz="0 0 0" />
            <geometry>
                <mesh filename="package://airbot_play_v2_1/meshes/link6.STL" />
            </geometry>
            <material name="">
                <color rgba="0.698039215686274 0.698039215686274 0.698039215686274 1" />
            </material>
        </visual>
        <collision>
            <origin rpy="0 0 0" xyz="0 0 0" />
            <geometry>
                <mesh filename="package://airbot_play_v2_1/meshes/link6.STL" />
            </geometry>
        </collision>
    </link>
    <joint name="right_joint6" type="revolute">
        <origin rpy="0 1.5708 0" xyz="0.0865 0 -0.0027486" />
        <parent link="right_link5" />
        <child link="right_link6" />
        <axis xyz="0 0 1" />
        <limit effort="0" lower="-3.14" upper="3.14" velocity="0" />
    </joint>
    <!-- airbot_twins_body mass -->
    <!-- airbot_twins_body joint and link -->
    <link name="body_link">
        <visual>
            <geometry>
                <box size="0.01 0.025 0.025" />
            </geometry>
            <origin rpy="0.0 0.0 0.0" xyz="0.0 0.0 0.0" />
            <material name="black" />
        </visual>
        <collision>
            <geometry>
                <box size="0.01 0.025 0.025" />
            </geometry>
            <origin rpy="0.0 0.0 0.0" xyz="0.0 0.0 0.0" />
        </collision>
        <inertial>
            <mass value="0.1" />
            <inertia ixx="6.0416666666666675e-06" ixy="0" ixz="0" iyy="6.0416666666666675e-06" iyz="0" izz="1.041666666666667e-05" />
            <origin xyz="0 0 0" rpy="0 0 0" />
        </inertial>
    </link>
    <gazebo reference="body_link">
        <material>Gazebo/Blue</material>
        <plugin name="gazebo_ros_control">
            <robotNamespace>/</robotNamespace>
        </plugin>
    </gazebo>
    <joint name="left_arm_joint" type="fixed">
        <origin rpy="0 0 0" xyz="0 0 -0.135" />
        <parent link="left_base_link" />
        <child link="body_link" />
    </joint>
    <joint name="right_arm_joint" type="fixed">
        <origin rpy="3.1416 0 0" xyz="0 0 -0.135" />
        <parent link="body_link" />
        <child link="right_base_link" />
    </joint>
    <transmission name="trans_left_joint1">
        <type>transmission_interface/SimpleTransmission</type>
        <joint name="left_joint1">
            <hardwareInterface>hardware_interface/PositionJointInterface</hardwareInterface>
        </joint>
        <actuator name="left_joint1_motor">
            <hardwareInterface>hardware_interface/PositionJointInterface</hardwareInterface>
            <mechanicalReduction>1</mechanicalReduction>
        </actuator>
    </transmission>
    <transmission name="trans_left_joint2">
        <type>transmission_interface/SimpleTransmission</type>
        <joint name="left_joint2">
            <hardwareInterface>hardware_interface/PositionJointInterface</hardwareInterface>
        </joint>
        <actuator name="left_joint2_motor">
            <hardwareInterface>hardware_interface/PositionJointInterface</hardwareInterface>
            <mechanicalReduction>1</mechanicalReduction>
        </actuator>
    </transmission>
    <transmission name="trans_left_joint3">
        <type>transmission_interface/SimpleTransmission</type>
        <joint name="left_joint3">
            <hardwareInterface>hardware_interface/PositionJointInterface</hardwareInterface>
        </joint>
        <actuator name="left_joint3_motor">
            <hardwareInterface>hardware_interface/PositionJointInterface</hardwareInterface>
            <mechanicalReduction>1</mechanicalReduction>
        </actuator>
    </transmission>
    <transmission name="trans_left_joint4">
        <type>transmission_interface/SimpleTransmission</type>
        <joint name="left_joint4">
            <hardwareInterface>hardware_interface/PositionJointInterface</hardwareInterface>
        </joint>
        <actuator name="left_joint4_motor">
            <hardwareInterface>hardware_interface/PositionJointInterface</hardwareInterface>
            <mechanicalReduction>1</mechanicalReduction>
        </actuator>
    </transmission>
    <transmission name="trans_left_joint5">
        <type>transmission_interface/SimpleTransmission</type>
        <joint name="left_joint5">
            <hardwareInterface>hardware_interface/PositionJointInterface</hardwareInterface>
        </joint>
        <actuator name="left_joint5_motor">
            <hardwareInterface>hardware_interface/PositionJointInterface</hardwareInterface>
            <mechanicalReduction>1</mechanicalReduction>
        </actuator>
    </transmission>
    <transmission name="trans_left_joint6">
        <type>transmission_interface/SimpleTransmission</type>
        <joint name="left_joint6">
            <hardwareInterface>hardware_interface/PositionJointInterface</hardwareInterface>
        </joint>
        <actuator name="left_joint6_motor">
            <hardwareInterface>hardware_interface/PositionJointInterface</hardwareInterface>
            <mechanicalReduction>1</mechanicalReduction>
        </actuator>
    </transmission>
    <transmission name="trans_right_joint1">
        <type>transmission_interface/SimpleTransmission</type>
        <joint name="right_joint1">
            <hardwareInterface>hardware_interface/PositionJointInterface</hardwareInterface>
        </joint>
        <actuator name="right_joint1_motor">
            <hardwareInterface>hardware_interface/PositionJointInterface</hardwareInterface>
            <mechanicalReduction>1</mechanicalReduction>
        </actuator>
    </transmission>
    <transmission name="trans_right_joint2">
        <type>transmission_interface/SimpleTransmission</type>
        <joint name="right_joint2">
            <hardwareInterface>hardware_interface/PositionJointInterface</hardwareInterface>
        </joint>
        <actuator name="right_joint2_motor">
            <hardwareInterface>hardware_interface/PositionJointInterface</hardwareInterface>
            <mechanicalReduction>1</mechanicalReduction>
        </actuator>
    </transmission>
    <transmission name="trans_right_joint3">
        <type>transmission_interface/SimpleTransmission</type>
        <joint name="right_joint3">
            <hardwareInterface>hardware_interface/PositionJointInterface</hardwareInterface>
        </joint>
        <actuator name="right_joint3_motor">
            <hardwareInterface>hardware_interface/PositionJointInterface</hardwareInterface>
            <mechanicalReduction>1</mechanicalReduction>
        </actuator>
    </transmission>
    <transmission name="trans_right_joint4">
        <type>transmission_interface/SimpleTransmission</type>
        <joint name="right_joint4">
            <hardwareInterface>hardware_interface/PositionJointInterface</hardwareInterface>
        </joint>
        <actuator name="right_joint4_motor">
            <hardwareInterface>hardware_interface/PositionJointInterface</hardwareInterface>
            <mechanicalReduction>1</mechanicalReduction>
        </actuator>
    </transmission>
    <transmission name="trans_right_joint5">
        <type>transmission_interface/SimpleTransmission</type>
        <joint name="right_joint5">
            <hardwareInterface>hardware_interface/PositionJointInterface</hardwareInterface>
        </joint>
        <actuator name="right_joint5_motor">
            <hardwareInterface>hardware_interface/PositionJointInterface</hardwareInterface>
            <mechanicalReduction>1</mechanicalReduction>
        </actuator>
    </transmission>
    <transmission name="trans_right_joint6">
        <type>transmission_interface/SimpleTransmission</type>
        <joint name="right_joint6">
            <hardwareInterface>hardware_interface/PositionJointInterface</hardwareInterface>
        </joint>
        <actuator name="right_joint6_motor">
            <hardwareInterface>hardware_interface/PositionJointInterface</hardwareInterface>
            <mechanicalReduction>1</mechanicalReduction>
        </actuator>
    </transmission>
</robot>

