<?xml version="1.0" encoding="utf-8" ?>
<!-- This URDF was automatically created by SolidWorks to URDF Exporter! Originally created by Stephen Brawner (brawner@gmail.com) 
     Commit Version: 1.6.0-4-g7f85cfe  Build Version: 1.6.7995.38578
     For more information, please see http://wiki.ros.org/sw_urdf_exporter -->
<robot name="airbot_play_v2_inspire_eg2_4c_v1">
    <link name="base_link">
        <inertial>
            <origin xyz="-0.0124323372191195 -0.000168577813282202 0.0371705356530249" rpy="0 0 0" />
            <mass value="0.36733" />
            <inertia ixx="0.00045941" ixy="0.00000455" ixz="-0.00000225" iyy="0.00072656" iyz="-0.00000316" izz="0.00089115" />
        </inertial>
        <visual>
            <origin xyz="0 0 0" rpy="0 0 0" />
            <geometry>
                <mesh filename="package://airbot_play_v2_inspire_eg2_4c_v1/meshes/base_link.STL" />
            </geometry>
            <material name="">
                <color rgba="1 1 1 1" />
            </material>
        </visual>
        <collision>
            <origin xyz="0 0 0" rpy="0 0 0" />
            <geometry>
                <mesh filename="package://airbot_play_v2_inspire_eg2_4c_v1/meshes/base_link.STL" />
            </geometry>
        </collision>
    </link>
    <link name="link1">
        <inertial>
            <origin xyz="-3.63839294803547E-09 0.00411602516522613 -0.0267160520548818" rpy="0 0 0" />
            <mass value="0.18684" />
            <inertia ixx="0.00023064" ixy="0.00000000" ixz="0.00000000" iyy="0.00007773" iyz="0.00001816" izz="0.00020593" />
        </inertial>
        <visual>
            <origin xyz="0 0 0" rpy="0 0 0" />
            <geometry>
                <mesh filename="package://airbot_play_v2_inspire_eg2_4c_v1/meshes/link1.STL" />
            </geometry>
            <material name="">
                <color rgba="0.898039215686275 0.917647058823529 0.929411764705882 1" />
            </material>
        </visual>
        <collision>
            <origin xyz="0 0 0" rpy="0 0 0" />
            <geometry>
                <mesh filename="package://airbot_play_v2_inspire_eg2_4c_v1/meshes/link1.STL" />
            </geometry>
        </collision>
    </link>
    <joint name="joint1" type="revolute">
        <origin xyz="0 0 0.113" rpy="0 0 0" />
        <parent link="base_link" />
        <child link="link1" />
        <axis xyz="0 0 1" />
        <limit lower="-2" upper="3.14" effort="100" velocity="110" />
    </joint>
    <link name="link2">
        <inertial>
            <origin xyz="0.131545428582519 4.45240788682355E-11 0.00203029636028226" rpy="0 0 0" />
            <mass value="0.76702" />
            <inertia ixx="0.00052958" ixy="0.00000000" ixz=" -0.00007564" iyy="0.00979918" iyz="0.00000000" izz="0.00967816" />
        </inertial>
        <visual>
            <origin xyz="0 0 0" rpy="0 0 0" />
            <geometry>
                <mesh filename="package://airbot_play_v2_inspire_eg2_4c_v1/meshes/link2.STL" />
            </geometry>
            <material name="">
                <color rgba="1 1 1 1" />
            </material>
        </visual>
        <collision>
            <origin xyz="0 0 0" rpy="0 0 0" />
            <geometry>
                <mesh filename="package://airbot_play_v2_inspire_eg2_4c_v1/meshes/link2.STL" />
            </geometry>
        </collision>
    </link>
    <joint name="joint2" type="revolute">
        <origin xyz="0 0 0" rpy="-1.5708 -0.12153 3.1416" />
        <parent link="link1" />
        <child link="link2" />
        <axis xyz="0 0 1" />
        <limit lower="-3.14" upper="0" effort="100" velocity="110" />
    </joint>
    <link name="link3">
        <inertial>
            <origin xyz="0.0370972581725279 -0.118875003827638 0.00162919798688163" rpy="0 0 0" />
            <mass value="0.53744102" />
            <inertia ixx="0.00669513" ixy="-0.00112098" ixz="-0.00003936" iyy="0.00085647" iyz="0.00011902" izz="0.00674459" />
        </inertial>
        <visual>
            <origin xyz="0 0 0" rpy="0 0 0" />
            <geometry>
                <mesh filename="package://airbot_play_v2_inspire_eg2_4c_v1/meshes/link3.STL" />
            </geometry>
            <material name="">
                <color rgba="0.752941176470588 0.752941176470588 0.752941176470588 1" />
            </material>
        </visual>
        <collision>
            <origin xyz="0 0 0" rpy="0 0 0" />
            <geometry>
                <mesh filename="package://airbot_play_v2_inspire_eg2_4c_v1/meshes/link3.STL" />
            </geometry>
        </collision>
    </link>
    <joint name="joint3" type="revolute">
        <origin xyz="0.264 0 0.00075" rpy="0 0 -1.4493" />
        <parent link="link2" />
        <child link="link3" />
        <axis xyz="0 0 1" />
        <limit lower="0" upper="3.9" effort="100" velocity="110" />
    </joint>
    <link name="link4">
        <inertial>
            <origin xyz="-0.000141113671203535 -9.34593691326313E-08 -0.00664660834537212" rpy="0 0 0" />
            <mass value="0.146399866976371" />
            <inertia ixx="0.00008099" ixy="0.00000000" ixz="0.00000138" iyy="0.00007723" iyz="0.00000000" izz="0.00005735" />
        </inertial>
        <visual>
            <origin xyz="0 0 0" rpy="0 0 0" />
            <geometry>
                <mesh filename="package://airbot_play_v2_inspire_eg2_4c_v1/meshes/link4.STL" />
            </geometry>
            <material name="">
                <color rgba="0.752941176470588 0.752941176470588 0.752941176470588 1" />
            </material>
        </visual>
        <collision>
            <origin xyz="0 0 0" rpy="0 0 0" />
            <geometry>
                <mesh filename="package://airbot_play_v2_inspire_eg2_4c_v1/meshes/link4.STL" />
            </geometry>
        </collision>
    </link>
    <joint name="joint4" type="revolute">
        <origin xyz="0.056 -0.3245 0" rpy="1.5708 0 0" />
        <parent link="link3" />
        <child link="link4" />
        <axis xyz="0 0 1" />
        <limit lower="-4" upper="4" effort="100" velocity="110" />
    </joint>
    <link name="link5">
        <inertial>
            <origin xyz="-0.0402748939533359 -4.34158851685199E-05 -0.00162843014239708" rpy="0 0 0" />
            <mass value="0.183711883205063" />
            <inertia ixx="0.00010730" ixy="-0.00000006" ixz="-0.00002691" iyy="0.00018017" iyz="0.00000000" izz="0.00015131" />
        </inertial>
        <visual>
            <origin xyz="0 0 0" rpy="0 0 0" />
            <geometry>
                <mesh filename="package://airbot_play_v2_inspire_eg2_4c_v1/meshes/link5.STL" />
            </geometry>
            <material name="">
                <color rgba="1 1 1 1" />
            </material>
        </visual>
        <collision>
            <origin xyz="0 0 0" rpy="0 0 0" />
            <geometry>
                <mesh filename="package://airbot_play_v2_inspire_eg2_4c_v1/meshes/link5.STL" />
            </geometry>
        </collision>
    </link>
    <joint name="joint5" type="revolute">
        <origin xyz="0 0 0" rpy="0 1.5708 1.5708" />
        <parent link="link4" />
        <child link="link5" />
        <axis xyz="0 0 1" />
        <limit lower="-1.4" upper="1.57" effort="100" velocity="110" />
    </joint>
    <link name="gripper_link">
        <inertial>
            <origin xyz="-0.000179 -0.012920 0.115245" rpy="0 0 0" />
            <mass value="0.202483822224683" />
            <inertia ixx="8.72656224038094E-05" ixy="2.1157802312087E-09" ixz="4.46212258304102E-07" iyy="0.000110884338373626" iyz="3.53923491606382E-06" izz="9.50216775187288E-05" />
        </inertial>
        <visual>
            <origin xyz="0 0 -0.003" rpy="0 0 0" />
            <geometry>
                <mesh filename="package://airbot_play_inspire_eg2_4c_v2/meshes/gripper_link.STL" />
            </geometry>
            <material name="">
                <color rgba="0.792156862745098 0.819607843137255 0.933333333333333 1" />
            </material>
        </visual>
        <collision>
            <origin xyz="0 0 -0.003" rpy="0 0 0" />
            <geometry>
                <mesh filename="package://airbot_play_inspire_eg2_4c_v2/meshes/gripper_link.STL" />
            </geometry>
        </collision>
    </link>
    <joint name="joint6" type="revolute">
        <origin xyz="0 0 0" rpy="0 -1.5708 0" />
        <parent link="link5" />
        <child link="gripper_link" />
        <axis xyz="0 0 1" />
        <limit lower="-10" upper="10" effort="100" velocity="1000" />
    </joint>
    <link name="gripper_link10">
        <inertial>
            <origin xyz="0.0162376775855017 0.00170828143838967 1.60704782814491E-14" rpy="0 0 0" />
            <mass value="0.00248574193257273" />
            <inertia ixx="1.1187321281772E-07" ixy="-6.68088965340704E-19" ixz="-1.14085928959275E-18" iyy="6.84359115875508E-07" iyz="-3.99246934174549E-19" izz="5.89072994948579E-07" />
        </inertial>
        <visual>
            <origin xyz="0 0 0" rpy="0 0 0" />
            <geometry>
                <mesh filename="package://airbot_play_inspire_eg2_4c_v2/meshes/gripper_link10.STL" />
            </geometry>
            <material name="">
                <color rgba="0.792156862745098 0.819607843137255 0.933333333333333 1" />
            </material>
        </visual>
        <collision>
            <origin xyz="0 0 0" rpy="0 0 0" />
            <geometry>
                <mesh filename="package://airbot_play_inspire_eg2_4c_v2/meshes/gripper_link10.STL" />
            </geometry>
        </collision>
    </link>
    <joint name="joint_gripper10" type="revolute">
        <origin xyz="-0.038533 0.00036 0.18735" rpy="-1.5708 -1.304 3.1416" />
        <parent link="gripper_link" />
        <child link="gripper_link10" />
        <axis xyz="0 0 1" />
        <limit lower="-10" upper="10" effort="100" velocity="110" />
    </joint>
    <link name="gripper_link11">
        <inertial>
            <origin xyz="-0.0110043692378349 0.00972866237979003 -3.15436854414486E-09" rpy="0 0 0" />
            <mass value="0.00450681926243327" />
            <inertia ixx="1.99225999101227E-07" ixy="9.189631443366E-08" ixz="1.32669175648538E-13" iyy="5.14550853833888E-07" iyz="-4.49972931710022E-14" izz="5.32027763416069E-07" />
        </inertial>
        <visual>
            <origin xyz="0 0 0" rpy="0 0 0" />
            <geometry>
                <mesh filename="package://airbot_play_inspire_eg2_4c_v2/meshes/gripper_link11.STL" />
            </geometry>
            <material name="">
                <color rgba="0.792156862745098 0.819607843137255 0.933333333333333 1" />
            </material>
        </visual>
        <collision>
            <origin xyz="0 0 0" rpy="0 0 0" />
            <geometry>
                <mesh filename="package://airbot_play_inspire_eg2_4c_v2/meshes/gripper_link11.STL" />
            </geometry>
        </collision>
    </link>
    <joint name="joint_gripper11" type="revolute">
        <origin xyz="0.041998 -0.00037577 0" rpy="0 0 2.8658" />
        <parent link="gripper_link10" />
        <child link="gripper_link11" />
        <axis xyz="0 0 1" />
        <limit lower="-10" upper="10" effort="100" velocity="110" />
    </joint>
    <link name="gripper_link20">
        <inertial>
            <origin xyz="0.0160458916846533 0.00170815882510347 -1.61815005839117E-14" rpy="0 0 0" />
            <mass value="0.0024857419325728" />
            <inertia ixx="1.11873212817726E-07" ixy="6.5445041140093E-19" ixz="1.13838047913434E-18" iyy="6.84359115875493E-07" iyz="-3.98790262211301E-19" izz="5.8907299494856E-07" />
        </inertial>
        <visual>
            <origin xyz="0 0 0" rpy="0 0 0" />
            <geometry>
                <mesh filename="package://airbot_play_inspire_eg2_4c_v2/meshes/gripper_link20.STL" />
            </geometry>
            <material name="">
                <color rgba="0.792156862745098 0.819607843137255 0.933333333333333 1" />
            </material>
        </visual>
        <collision>
            <origin xyz="0 0 0" rpy="0 0 0" />
            <geometry>
                <mesh filename="package://airbot_play_inspire_eg2_4c_v2/meshes/gripper_link20.STL" />
            </geometry>
        </collision>
    </link>
    <joint name="joint_gripper20" type="revolute">
        <origin xyz="0.041464 0.00036 0.18664" rpy="1.5708 -1.304 0" />
        <parent link="gripper_link" />
        <child link="gripper_link20" />
        <axis xyz="0 0 1" />
        <limit lower="-10" upper="10" effort="100" velocity="110" />
    </joint>
    <link name="gripper_link21">
        <inertial>
            <origin xyz="-0.0117059608928904 -0.0140030860218414 3.11077152925776E-09" rpy="0 0 0" />
            <mass value="0.00450681912675432" />
            <inertia ixx="2.02615006762524E-07" ixy="-9.74786442765277E-08" ixz="-1.30502494006714E-13" iyy="5.11161832405036E-07" iyz="-4.71432886532517E-14" izz="5.32027750665231E-07" />
        </inertial>
        <visual>
            <origin xyz="0 0 0" rpy="0 0 0" />
            <geometry>
                <mesh filename="package://airbot_play_inspire_eg2_4c_v2/meshes/gripper_link21.STL" />
            </geometry>
            <material name="">
                <color rgba="0.792156862745098 0.819607843137255 0.933333333333333 1" />
            </material>
        </visual>
        <collision>
            <origin xyz="0 0 0" rpy="0 0 0" />
            <geometry>
                <mesh filename="package://airbot_play_inspire_eg2_4c_v2/meshes/gripper_link21.STL" />
            </geometry>
        </collision>
    </link>
    <joint name="joint_gripper21" type="revolute">
        <origin xyz="0.041998 -0.00037577 0" rpy="0 0 -2.8837" />
        <parent link="gripper_link20" />
        <child link="gripper_link21" />
        <axis xyz="0 0 1" />
        <limit lower="-10" upper="10" effort="100" velocity="110" />
    </joint>
    <link name="custom_end_link">
        <inertial>
            <origin xyz="0 0 0" rpy="0 0 0" />
            <mass value="1E-15" />
            <inertia ixx="1E-11" ixy="1E-15" ixz="1E-15" iyy="1E-11" iyz="1E-15" izz="1E-11" />
        </inertial>
    </link>
    <joint name="joint_custom_end" type="fixed">
        <origin xyz="0 0 0.255" rpy="1.5708 -1.5708 0" />
        <parent link="gripper_link" />
        <child link="custom_end_link" />
    </joint>
    <transmission name="trans_joint1">
        <type>transmission_interface/SimpleTransmission</type>
        <joint name="joint1">
            <hardwareInterface>hardware_interface/PositionJointInterface</hardwareInterface>
        </joint>
        <actuator name="joint1_motor">
            <hardwareInterface>hardware_interface/PositionJointInterface</hardwareInterface>
            <mechanicalReduction>1</mechanicalReduction>
        </actuator>
    </transmission>
    <transmission name="trans_joint2">
        <type>transmission_interface/SimpleTransmission</type>
        <joint name="joint2">
            <hardwareInterface>hardware_interface/PositionJointInterface</hardwareInterface>
        </joint>
        <actuator name="joint2_motor">
            <hardwareInterface>hardware_interface/PositionJointInterface</hardwareInterface>
            <mechanicalReduction>1</mechanicalReduction>
        </actuator>
    </transmission>
    <transmission name="trans_joint3">
        <type>transmission_interface/SimpleTransmission</type>
        <joint name="joint3">
            <hardwareInterface>hardware_interface/PositionJointInterface</hardwareInterface>
        </joint>
        <actuator name="joint3_motor">
            <hardwareInterface>hardware_interface/PositionJointInterface</hardwareInterface>
            <mechanicalReduction>1</mechanicalReduction>
        </actuator>
    </transmission>
    <transmission name="trans_joint4">
        <type>transmission_interface/SimpleTransmission</type>
        <joint name="joint4">
            <hardwareInterface>hardware_interface/PositionJointInterface</hardwareInterface>
        </joint>
        <actuator name="joint4_motor">
            <hardwareInterface>hardware_interface/PositionJointInterface</hardwareInterface>
            <mechanicalReduction>1</mechanicalReduction>
        </actuator>
    </transmission>
    <transmission name="trans_joint5">
        <type>transmission_interface/SimpleTransmission</type>
        <joint name="joint5">
            <hardwareInterface>hardware_interface/PositionJointInterface</hardwareInterface>
        </joint>
        <actuator name="joint5_motor">
            <hardwareInterface>hardware_interface/PositionJointInterface</hardwareInterface>
            <mechanicalReduction>1</mechanicalReduction>
        </actuator>
    </transmission>
    <transmission name="trans_joint6">
        <type>transmission_interface/SimpleTransmission</type>
        <joint name="joint6">
            <hardwareInterface>hardware_interface/PositionJointInterface</hardwareInterface>
        </joint>
        <actuator name="joint6_motor">
            <hardwareInterface>hardware_interface/PositionJointInterface</hardwareInterface>
            <mechanicalReduction>1</mechanicalReduction>
        </actuator>
    </transmission>
    <transmission name="trans_joint_gripper10">
        <type>transmission_interface/SimpleTransmission</type>
        <joint name="joint_gripper10">
            <hardwareInterface>hardware_interface/PositionJointInterface</hardwareInterface>
        </joint>
        <actuator name="joint_gripper10_motor">
            <hardwareInterface>hardware_interface/PositionJointInterface</hardwareInterface>
            <mechanicalReduction>1</mechanicalReduction>
        </actuator>
    </transmission>
    <transmission name="trans_joint_gripper11">
        <type>transmission_interface/SimpleTransmission</type>
        <joint name="joint_gripper11">
            <hardwareInterface>hardware_interface/PositionJointInterface</hardwareInterface>
        </joint>
        <actuator name="joint_gripper11_motor">
            <hardwareInterface>hardware_interface/PositionJointInterface</hardwareInterface>
            <mechanicalReduction>1</mechanicalReduction>
        </actuator>
    </transmission>
    <transmission name="trans_joint_gripper20">
        <type>transmission_interface/SimpleTransmission</type>
        <joint name="joint_gripper20">
            <hardwareInterface>hardware_interface/PositionJointInterface</hardwareInterface>
        </joint>
        <actuator name="joint_gripper20_motor">
            <hardwareInterface>hardware_interface/PositionJointInterface</hardwareInterface>
            <mechanicalReduction>1</mechanicalReduction>
        </actuator>
    </transmission>
    <transmission name="trans_joint_gripper21">
        <type>transmission_interface/SimpleTransmission</type>
        <joint name="joint_gripper21">
            <hardwareInterface>hardware_interface/PositionJointInterface</hardwareInterface>
        </joint>
        <actuator name="joint_gripper21_motor">
            <hardwareInterface>hardware_interface/PositionJointInterface</hardwareInterface>
            <mechanicalReduction>1</mechanicalReduction>
        </actuator>
    </transmission>
    <gazebo>
        <plugin name="gazebo_ros_control">
            <robotNamespace>/</robotNamespace>
        </plugin>
    </gazebo>
</robot>

